Workbook
Name Argentina: Bilder!$B$2
Name Australien: Bilder!$B$3
Name Belgien: Bilder!$B$4
Name BILDFRI: Bilder!$B$34
Name Brasilien: Bilder!$B$5
Name Brons: INDIRECT(Beräkningar!$AA$54)
Name CostaRica: Bilder!$B$6
Name Danmark: Bilder!$B$7
Name Ecuador: Bilder!$B$8
Name Egypten: Bilder!$B$8
Name England: Bilder!$B$9
Name Final1a: INDIRECT(Beräkningar!$X$52)
Name Final1b: INDIRECT(Beräkningar!$Y$52)
Name Final2a: INDIRECT(Beräkningar!$X$70)
Name Final2b: INDIRECT(Beräkningar!$Y$70)
Name Fjärdeplats: INDIRECT(Beräkningar!$AA$55)
Name Frankrike: Bilder!$B$10
Name Ghana: Bilder!$B$11
Name Guld: INDIRECT(Beräkningar!$AA$52)
Name Iran: Bilder!$B$12
Name Japan: Bilder!$B$13
Name Kamerun: Bilder!$B$14
Name Kanada: Bilder!$B$15
Name Kroatien: Bilder!$B$16
Name Kvartsfinal1a: INDIRECT(Beräkningar!$R$52)
Name Kvartsfinal1b: INDIRECT(Beräkningar!$S$52)
Name Kvartsfinal2a: INDIRECT(Beräkningar!$R$55)
Name Kvartsfinal2b: INDIRECT(Beräkningar!$S$55)
Name Kvartsfinal3a: INDIRECT(Beräkningar!$R$70)
Name Kvartsfinal3b: INDIRECT(Beräkningar!$S$70)
Name Kvartsfinal4a: INDIRECT(Beräkningar!$R$73)
Name Kvartsfinal4b: INDIRECT(Beräkningar!$S$73)
Name Marocko: Bilder!$B$17
Name Mexiko: Bilder!$B$18
Name Nederländerna: Bilder!$B$19
Name Nigeria: Bilder!$B$19
Name Polen: Bilder!$B$20
Name Portugal: Bilder!$B$21
Name Qatar: Bilder!$B$22
Name Ryssland: Bilder!$B$22
Name Saudiarabien: Bilder!$B$23
Name Schweiz: Bilder!$B$24
Name Semifinal1a: INDIRECT(Beräkningar!$U$52)
Name Semifinal1b: INDIRECT(Beräkningar!$V$52)
Name Semifinal2a: INDIRECT(Beräkningar!$U$70)
Name Semifinal2b: INDIRECT(Beräkningar!$V$70)
Name Senegal: Bilder!$B$25
Name Serbien: Bilder!$B$26
Name Silver: INDIRECT(Beräkningar!$AA$53)
Name Spanien: Bilder!$B$27
Name Sydkorea: Bilder!$B$28
Name Tunisien: Bilder!$B$29
Name Tyskland: Bilder!$B$30
Name Uruguay: Bilder!$B$31
Name USA: Bilder!$B$32
Name Wales: Bilder!$B$33
Name Åttondel1a: INDIRECT(Beräkningar!$N$52)
Name Åttondel1b: INDIRECT(Beräkningar!$O$52)
Name Åttondel2a: INDIRECT(Beräkningar!$N$55)
Name Åttondel2b: INDIRECT(Beräkningar!$O$55)

Sheet Tippa
C2: VM-Tips Qatar 2022 | D2: SISTA DAG FÖR INLÄMNING 19 NOVEMBER kl 23:59
C3: Mitt Namn: Jonathan Behr Mattsson | D3: =IF(SUM(J27,J38,J49,J60,J71,J82,T37,J93,J104)=0,"Alla kontroller i arket Tippa är OK","Ditt tips innehåller fel") -> Alla kontroller i arket Tippa är OK
A4: - | K4: För spelsschema se: | R4: Hur bör man ranka lagen
A5: 1 | C5: Insats 230 kr: Betalas till Dan Spinelli Scala via alternativ: | K5: http://www.vm-fotboll.se/ | R5: 1. Poängen i alla gruppmatcher, med 3 poäng vid vinst, 1 poäng vid oavgjort och 0 poäng vid förlust.
A6: 2 | C6: Bankkonto: Handelsbanken, clearing: 6138 konto: 642 445 648 | R6: 2. Målskillnad i alla gruppmatcher
A7: 3 | C7: Swish: 072-301 80 23 | R7: 3. Gjorda mål i alla gruppmatcher
A8: 4 | C8: Notera: 30 kr avser administrationsavgift | K8: Vinstfördelning = Prisplats (%) * Antal deltagare (#) * 200 (kr) | R8: 4. Poäng i matcherna mellan likaplacerade lag - EJ BEAKTAT
K9: Vinstfördelning | R9: 5. Målskillnad i matcherna mellan likaplacerade lag - EJ BEAKTAT
A10: - | C10: Full anmälan sker när ifyllt dokument är skickat och inbetalningen är registererad | K10: Plats | M10: Premie | R10: 6. Gjorda mål i matcherna mellan likaplacerade lag - EJ BEAKTAT
A11: 0 | C11: Gå gärna med i vår facebookgrupp för att kanske ta del av löpande resultat: | K11: 1 | M11: 0.45 | R11: 7. Fair play-poäng - EJ BEAKTAT
A12: 1 | C12: Facebookgrupp: VM-Tips 2022 - Med dromedar till Qatar? | K12: 2 | M12: 0.25 | R12: 8. Lottdragning - EJ BEAKTAT
A13: 2 | C13: Du kan även använda rättningsfliken för att själv hålla koll på dina poäng | K13: 3 | M13: 0.15
A14: 3 | K14: 4 | M14: 0.1
A15: 4 | C15: Vid frågor ring eller maila Dan eller Niklas på: | K15: 5 | M15: 0.05
A16: 5 | C16: Dan, 072 301 80 23, danspinelli@hotmail.com
A17: 6 | C17: Niklas , 073 628 28 94, niklas.zanderholm@gmail.com
A18: 7
A19: 8 | C19: 1. Tippa gruppspelet | O19: 2. Tippa slutspelet
A20: 9 | C20: =IF(SUM(J27,J38,J49,J60,J71,J82,T37)=0,"Alla kontroller OK","Ditt tips innehåller fel") -> Alla kontroller OK
A21: 10
A22: - | C22: Grupp A | D22: Datum | E22: Tid | F22: 1X2 | G22: Resultat | J22: Plac. | K22: Grupp A | L22: Poäng | M22: Ändra placering | P22: Åttondelsfinaler | Q22: Kvartsfinaler | R22: Semifinaler | T22: Finaler | V22: Semifinaler | W22: Kvartsfinaler | X22: Åttondelsfinaler
A23: A1 | C23: =INDEX(Beräkningar!$G$4:$G$51,MATCH(A23,Beräkningar!$K$4:$K$51,0))&" - "&INDEX(Beräkningar!$H$4:$H$51,MATCH(A23,Beräkningar!$K$4:$K$51,0)) -> Qatar - Ecuador | D23: =INDEX(Beräkningar!$B$4:$B$51,MATCH(A23,Beräkningar!$K$4:$K$51,0)) -> Sön 20/11 | E23: =INDEX(Beräkningar!$C$4:$C$51,MATCH(A23,Beräkningar!$K$4:$K$51,0)) -> 0.70833333 | F23: =IF(OR(G23="-",H23="-"),"-",IF(G23>H23,1,IF(G23=H23,"X",2))) -> X | G23: 1 | H23: 1 | J23: =IF(M23="-",1,IF(M23=0,1,M23)) -> 1 | K23: =Beräkningar!AG4 -> Nederländerna | L23: =Beräkningar!AH4 -> 9 | M23: - | P23: =IF(F28="-","",Beräkningar!N52) -> Nederländerna | X23: =IF(F39="-","",Beräkningar!N58) -> England
A24: A2 | C24: =INDEX(Beräkningar!$G$4:$G$51,MATCH(A24,Beräkningar!$K$4:$K$51,0))&" - "&INDEX(Beräkningar!$H$4:$H$51,MATCH(A24,Beräkningar!$K$4:$K$51,0)) -> Senegal - Nederländerna | D24: =INDEX(Beräkningar!$B$4:$B$51,MATCH(A24,Beräkningar!$K$4:$K$51,0)) -> Mån 21/11 | E24: =INDEX(Beräkningar!$C$4:$C$51,MATCH(A24,Beräkningar!$K$4:$K$51,0)) -> 0.70833333 | F24: =IF(OR(G24="-",H24="-"),"-",IF(G24>H24,1,IF(G24=H24,"X",2))) -> 2 | G24: 0 | H24: 2 | J24: =IF(M24="-",2,IF(M24=0,2,M24)) -> 2 | K24: =Beräkningar!AG5 -> Senegal | L24: =Beräkningar!AH5 -> 6 | M24: - | P24: vs. | Q24: Nederländerna | W24: England | X24: vs.
A25: A3 | C25: =INDEX(Beräkningar!$G$4:$G$51,MATCH(A25,Beräkningar!$K$4:$K$51,0))&" - "&INDEX(Beräkningar!$H$4:$H$51,MATCH(A25,Beräkningar!$K$4:$K$51,0)) -> Qatar - Senegal | D25: =INDEX(Beräkningar!$B$4:$B$51,MATCH(A25,Beräkningar!$K$4:$K$51,0)) -> Fre 25/11 | E25: =INDEX(Beräkningar!$C$4:$C$51,MATCH(A25,Beräkningar!$K$4:$K$51,0)) -> 0.58333333 | F25: =IF(OR(G25="-",H25="-"),"-",IF(G25>H25,1,IF(G25=H25,"X",2))) -> 2 | G25: 0 | H25: 2 | J25: =IF(M25="-",3,IF(M25=0,3,M25)) -> 3 | K25: =Beräkningar!AG6 -> Ecuador | L25: =Beräkningar!AH6 -> 1 | M25: - | P25: =IF(F39="-","",Beräkningar!O52) -> USA | X25: =IF(F28="-","",Beräkningar!O58) -> Senegal
A26: A4 | C26: =INDEX(Beräkningar!$G$4:$G$51,MATCH(A26,Beräkningar!$K$4:$K$51,0))&" - "&INDEX(Beräkningar!$H$4:$H$51,MATCH(A26,Beräkningar!$K$4:$K$51,0)) -> Nederländerna - Ecuador | D26: =INDEX(Beräkningar!$B$4:$B$51,MATCH(A26,Beräkningar!$K$4:$K$51,0)) -> Fre 25/11 | E26: =INDEX(Beräkningar!$C$4:$C$51,MATCH(A26,Beräkningar!$K$4:$K$51,0)) -> 0.70833333 | F26: =IF(OR(G26="-",H26="-"),"-",IF(G26>H26,1,IF(G26=H26,"X",2))) -> 1 | G26: 1 | H26: 0 | J26: =IF(M26="-",4,IF(M26=0,4,M26)) -> 4 | K26: =Beräkningar!AG7 -> Qatar | L26: =Beräkningar!AH7 -> 1 | M26: - | Q26: vs. | R26: Argentina | V26: Frankrike | W26: vs.
A27: A5 | C27: =INDEX(Beräkningar!$G$4:$G$51,MATCH(A27,Beräkningar!$K$4:$K$51,0))&" - "&INDEX(Beräkningar!$H$4:$H$51,MATCH(A27,Beräkningar!$K$4:$K$51,0)) -> Ecuador - Senegal | D27: =INDEX(Beräkningar!$B$4:$B$51,MATCH(A27,Beräkningar!$K$4:$K$51,0)) -> Tis 29/11 | E27: =INDEX(Beräkningar!$C$4:$C$51,MATCH(A27,Beräkningar!$K$4:$K$51,0)) -> 0.66666667 | F27: =IF(OR(G27="-",H27="-"),"-",IF(G27>H27,1,IF(G27=H27,"X",2))) -> 2 | G27: 0 | H27: 1 | J27: =IF(MAX(Beräkningar!AL4:AL7)>1,1,0) -> 0 | K27: Korrekt angivet (får ej vara dubbletter) | P27: =IF(F50="-","",Beräkningar!N55) -> Argentina | T27: Segrare Final | X27: =IF(F61="-","",Beräkningar!N61) -> Frankrike
A28: A6 | C28: =INDEX(Beräkningar!$G$4:$G$51,MATCH(A28,Beräkningar!$K$4:$K$51,0))&" - "&INDEX(Beräkningar!$H$4:$H$51,MATCH(A28,Beräkningar!$K$4:$K$51,0)) -> Nederländerna - Qatar | D28: =INDEX(Beräkningar!$B$4:$B$51,MATCH(A28,Beräkningar!$K$4:$K$51,0)) -> Tis 29/11 | E28: =INDEX(Beräkningar!$C$4:$C$51,MATCH(A28,Beräkningar!$K$4:$K$51,0)) -> 0.66666667 | F28: =IF(OR(G28="-",H28="-"),"-",IF(G28>H28,1,IF(G28=H28,"X",2))) -> 1 | G28: 3 | H28: 0 | P28: vs. | Q28: Argentina | T28: Brasilien | W28: Frankrike | X28: vs.
C29: Summa | P29: =IF(F61="-","",Beräkningar!O55) -> Danmark | S29: Brasilien | T29: vs. | U29: Frankrike | X29: =IF(F50="-","",Beräkningar!O61) -> Mexiko
C30: Bonus (30 / 50 poäng)
C31: Totalt | R31: vs. | T31: Segrare Bronsmatch | V31: vs.
P32: =IF(F72="-","",Beräkningar!N70) -> Tyskland | T32: Spanien | X32: =IF(F83="-","",Beräkningar!N76) -> Belgien
C33: Grupp B | D33: Datum | E33: Tid | F33: 1X2 | G33: Resultat | J33: Plac. | K33: Grupp B | L33: Poäng | M33: Ändra placering | P33: vs. | Q33: Tyskland | S33: =Beräkningar!X70 -> Argentina | T33: vs. | U33: =Beräkningar!Y70 -> Spanien | W33: Spanien | X33: vs.
A34: B1 | C34: =INDEX(Beräkningar!$G$4:$G$51,MATCH(A34,Beräkningar!$K$4:$K$51,0))&" - "&INDEX(Beräkningar!$H$4:$H$51,MATCH(A34,Beräkningar!$K$4:$K$51,0)) -> USA - Wales | D34: =INDEX(Beräkningar!$B$4:$B$51,MATCH(A34,Beräkningar!$K$4:$K$51,0)) -> Mån 21/11 | E34: =INDEX(Beräkningar!$C$4:$C$51,MATCH(A34,Beräkningar!$K$4:$K$51,0)) -> 0.83333333 | F34: =IF(OR(G34="-",H34="-"),"-",IF(G34>H34,1,IF(G34=H34,"X",2))) -> X | G34: 1 | H34: 1 | J34: =IF(M34="-",1,IF(M34=0,1,M34)) -> 1 | K34: =Beräkningar!AG9 -> England | L34: =Beräkningar!AH9 -> 5 | M34: - | P34: =IF(F83="-","",Beräkningar!O70) -> Kroatien | X34: =IF(F72="-","",Beräkningar!O76) -> Spanien
A35: B2 | C35: =INDEX(Beräkningar!$G$4:$G$51,MATCH(A35,Beräkningar!$K$4:$K$51,0))&" - "&INDEX(Beräkningar!$H$4:$H$51,MATCH(A35,Beräkningar!$K$4:$K$51,0)) -> England - Iran | D35: =INDEX(Beräkningar!$B$4:$B$51,MATCH(A35,Beräkningar!$K$4:$K$51,0)) -> Mån 21/11 | E35: =INDEX(Beräkningar!$C$4:$C$51,MATCH(A35,Beräkningar!$K$4:$K$51,0)) -> 0.58333333 | F35: =IF(OR(G35="-",H35="-"),"-",IF(G35>H35,1,IF(G35=H35,"X",2))) -> 1 | G35: 4 | H35: 0 | J35: =IF(M35="-",2,IF(M35=0,2,M35)) -> 2 | K35: =Beräkningar!AG10 -> USA | L35: =Beräkningar!AH10 -> 5 | M35: - | Q35: vs. | R35: Brasilien | V35: Spanien | W35: vs.
A36: B3 | C36: =INDEX(Beräkningar!$G$4:$G$51,MATCH(A36,Beräkningar!$K$4:$K$51,0))&" - "&INDEX(Beräkningar!$H$4:$H$51,MATCH(A36,Beräkningar!$K$4:$K$51,0)) -> England - USA | D36: =INDEX(Beräkningar!$B$4:$B$51,MATCH(A36,Beräkningar!$K$4:$K$51,0)) -> Fre 25/11 | E36: =INDEX(Beräkningar!$C$4:$C$51,MATCH(A36,Beräkningar!$K$4:$K$51,0)) -> 0.83333333 | F36: =IF(OR(G36="-",H36="-"),"-",IF(G36>H36,1,IF(G36=H36,"X",2))) -> X | G36: 2 | H36: 2 | J36: =IF(M36="-",3,IF(M36=0,3,M36)) -> 3 | K36: =Beräkningar!AG11 -> Wales | L36: =Beräkningar!AH11 -> 5 | M36: - | P36: =IF(F94="-","",Beräkningar!N73) -> Brasilien | X36: =IF(F105="-","",Beräkningar!N79) -> Portugal
A37: B4 | C37: =INDEX(Beräkningar!$G$4:$G$51,MATCH(A37,Beräkningar!$K$4:$K$51,0))&" - "&INDEX(Beräkningar!$H$4:$H$51,MATCH(A37,Beräkningar!$K$4:$K$51,0)) -> Wales - Iran | D37: =INDEX(Beräkningar!$B$4:$B$51,MATCH(A37,Beräkningar!$K$4:$K$51,0)) -> Fre 25/11 | E37: =INDEX(Beräkningar!$C$4:$C$51,MATCH(A37,Beräkningar!$K$4:$K$51,0)) -> 0.45833333 | F37: =IF(OR(G37="-",H37="-"),"-",IF(G37>H37,1,IF(G37=H37,"X",2))) -> 1 | G37: 2 | H37: 0 | J37: =IF(M37="-",4,IF(M37=0,4,M37)) -> 4 | K37: =Beräkningar!AG12 -> Iran | L37: =Beräkningar!AH12 -> 0 | M37: - | P37: vs. | Q37: Brasilien | T37: =Beräkningar!U84 -> 0 | W37: Portugal | X37: vs.
A38: B5 | C38: =INDEX(Beräkningar!$G$4:$G$51,MATCH(A38,Beräkningar!$K$4:$K$51,0))&" - "&INDEX(Beräkningar!$H$4:$H$51,MATCH(A38,Beräkningar!$K$4:$K$51,0)) -> Iran - USA | D38: =INDEX(Beräkningar!$B$4:$B$51,MATCH(A38,Beräkningar!$K$4:$K$51,0)) -> Tis 29/11 | E38: =INDEX(Beräkningar!$C$4:$C$51,MATCH(A38,Beräkningar!$K$4:$K$51,0)) -> 0.83333333 | F38: =IF(OR(G38="-",H38="-"),"-",IF(G38>H38,1,IF(G38=H38,"X",2))) -> 2 | G38: 1 | H38: 3 | J38: =IF(MAX(Beräkningar!AL9:AL12)>1,1,0) -> 0 | K38: Korrekt angivet (får ej vara dubbletter) | P38: =IF(F105="-","",Beräkningar!O73) -> Uruguay | T38: Korrekt angivet (kontrollerar att slutspelsträdet är uppdaterat) | X38: =IF(F94="-","",Beräkningar!O79) -> Kamerun
A39: B6 | C39: =INDEX(Beräkningar!$G$4:$G$51,MATCH(A39,Beräkningar!$K$4:$K$51,0))&" - "&INDEX(Beräkningar!$H$4:$H$51,MATCH(A39,Beräkningar!$K$4:$K$51,0)) -> Wales - England | D39: =INDEX(Beräkningar!$B$4:$B$51,MATCH(A39,Beräkningar!$K$4:$K$51,0)) -> Tis 29/11 | E39: =INDEX(Beräkningar!$C$4:$C$51,MATCH(A39,Beräkningar!$K$4:$K$51,0)) -> 0.83333333 | F39: =IF(OR(G39="-",H39="-"),"-",IF(G39>H39,1,IF(G39=H39,"X",2))) -> X | G39: 1 | H39: 1
C40: Summa
C41: Bonus (30 / 50 poäng) | O41: 3. Tippa turneringens första målskytt (ange enbart efternamn och stava rätt om du vill få poäng)
...

Sheet Rätta
C2: Här kan du föra in resultaten i turneringen så kommer din namnflik att rättas | L2: =Tippa!D3 -> Alla kontroller i arket Tippa är OK
C3: A. Ange resultat i gruppspel
A4: - | C4: (10p för rätt tecken + bonus 30p vid alla rätt, och 5p för rätt resultat + bonus 50p vid alla rätt.)
A5: Argentina
A6: Australien | C6: Rättning | L6: Ditt tips | M6: =Tippa!C3 -> Mitt Namn: Jonathan Behr Mattsson
A7: Belgien | C7: Grupp A | D7: 1X2 | E7: P | F7: Resultat | H7: P | J7: Bonus | L7: 1X2 | M7: Resultat
A8: Brasilien | C8: =Tippa!C23 -> Qatar - Ecuador | D8: =IF(F8="*","*",IF(F8>G8,1,IF(F8=G8,"X",IF(F8<G8,2,"error")))) -> * | E8: =(L8=D8)*$A$73 -> 0 | F8: * | G8: * | H8: =(F8=M8)*(G8=N8)*$A$77 -> 0 | J8: =+IF(SUM(H8:H13)=$A$77*6,$A$78,0) -> 0 | L8: =Tippa!F23 -> X | M8: =Tippa!G23 -> 1 | N8: =Tippa!H23 -> 1
A9: Colombia | C9: =Tippa!C24 -> Senegal - Nederländerna | D9: =IF(F9="*","*",IF(F9>G9,1,IF(F9=G9,"X",IF(F9<G9,2,"error")))) -> * | E9: =(L9=D9)*$A$73 -> 0 | F9: * | G9: * | H9: =(F9=M9)*(G9=N9)*$A$77 -> 0 | J9: =IF(SUM(E8:E13)=$A$73*6,$A$74,0) -> 0 | L9: =Tippa!F24 -> 2 | M9: =Tippa!G24 -> 0 | N9: =Tippa!H24 -> 2
A10: CostaRica | C10: =Tippa!C25 -> Qatar - Senegal | D10: =IF(F10="*","*",IF(F10>G10,1,IF(F10=G10,"X",IF(F10<G10,2,"error")))) -> * | E10: =(L10=D10)*$A$73 -> 0 | F10: * | G10: * | H10: =(F10=M10)*(G10=N10)*$A$77 -> 0 | L10: =Tippa!F25 -> 2 | M10: =Tippa!G25 -> 0 | N10: =Tippa!H25 -> 2
A11: Danmark | C11: =Tippa!C26 -> Nederländerna - Ecuador | D11: =IF(F11="*","*",IF(F11>G11,1,IF(F11=G11,"X",IF(F11<G11,2,"error")))) -> * | E11: =(L11=D11)*$A$73 -> 0 | F11: * | G11: * | H11: =(F11=M11)*(G11=N11)*$A$77 -> 0 | L11: =Tippa!F26 -> 1 | M11: =Tippa!G26 -> 1 | N11: =Tippa!H26 -> 0
A12: Egypten | C12: =Tippa!C27 -> Ecuador - Senegal | D12: =IF(F12="*","*",IF(F12>G12,1,IF(F12=G12,"X",IF(F12<G12,2,"error")))) -> * | E12: =(L12=D12)*$A$73 -> 0 | F12: * | G12: * | H12: =(F12=M12)*(G12=N12)*$A$77 -> 0 | L12: =Tippa!F27 -> 2 | M12: =Tippa!G27 -> 0 | N12: =Tippa!H27 -> 1
A13: England | C13: =Tippa!C28 -> Nederländerna - Qatar | D13: =IF(F13="*","*",IF(F13>G13,1,IF(F13=G13,"X",IF(F13<G13,2,"error")))) -> * | E13: =(L13=D13)*$A$73 -> 0 | F13: * | G13: * | H13: =(F13=M13)*(G13=N13)*$A$77 -> 0 | L13: =Tippa!F28 -> 1 | M13: =Tippa!G28 -> 3 | N13: =Tippa!H28 -> 0
A14: Frankrike
A15: Iran | C15: Grupp B | D15: 1X2 | E15: P | F15: Resultat | H15: P | J15: Bonus | L15: 1X2 | M15: Resultat
A16: Island | C16: =Tippa!C34 -> USA - Wales | D16: =IF(F16="*","*",IF(F16>G16,1,IF(F16=G16,"X",IF(F16<G16,2,"error")))) -> * | E16: =(L16=D16)*$A$73 -> 0 | F16: * | G16: * | H16: =(F16=M16)*(G16=N16)*$A$77 -> 0 | J16: =+IF(SUM(H16:H21)=$A$77*6,$A$78,0) -> 0 | L16: =Tippa!F34 -> X | M16: =Tippa!G34 -> 1 | N16: =Tippa!H34 -> 1
A17: Japan | C17: =Tippa!C35 -> England - Iran | D17: =IF(F17="*","*",IF(F17>G17,1,IF(F17=G17,"X",IF(F17<G17,2,"error")))) -> * | E17: =(L17=D17)*$A$73 -> 0 | F17: * | G17: * | H17: =(F17=M17)*(G17=N17)*$A$77 -> 0 | J17: =IF(SUM(E16:E21)=$A$73*6,$A$74,0) -> 0 | L17: =Tippa!F35 -> 1 | M17: =Tippa!G35 -> 4 | N17: =Tippa!H35 -> 0
A18: Kroatien | C18: =Tippa!C36 -> England - USA | D18: =IF(F18="*","*",IF(F18>G18,1,IF(F18=G18,"X",IF(F18<G18,2,"error")))) -> * | E18: =(L18=D18)*$A$73 -> 0 | F18: * | G18: * | H18: =(F18=M18)*(G18=N18)*$A$77 -> 0 | L18: =Tippa!F36 -> X | M18: =Tippa!G36 -> 2 | N18: =Tippa!H36 -> 2
A19: Marocko | C19: =Tippa!C37 -> Wales - Iran | D19: =IF(F19="*","*",IF(F19>G19,1,IF(F19=G19,"X",IF(F19<G19,2,"error")))) -> * | E19: =(L19=D19)*$A$73 -> 0 | F19: * | G19: * | H19: =(F19=M19)*(G19=N19)*$A$77 -> 0 | L19: =Tippa!F37 -> 1 | M19: =Tippa!G37 -> 2 | N19: =Tippa!H37 -> 0
A20: Mexiko | C20: =Tippa!C38 -> Iran - USA | D20: =IF(F20="*","*",IF(F20>G20,1,IF(F20=G20,"X",IF(F20<G20,2,"error")))) -> * | E20: =(L20=D20)*$A$73 -> 0 | F20: * | G20: * | H20: =(F20=M20)*(G20=N20)*$A$77 -> 0 | L20: =Tippa!F38 -> 2 | M20: =Tippa!G38 -> 1 | N20: =Tippa!H38 -> 3
A21: Nigeria | C21: =Tippa!C39 -> Wales - England | D21: =IF(F21="*","*",IF(F21>G21,1,IF(F21=G21,"X",IF(F21<G21,2,"error")))) -> * | E21: =(L21=D21)*$A$73 -> 0 | F21: * | G21: * | H21: =(F21=M21)*(G21=N21)*$A$77 -> 0 | L21: =Tippa!F39 -> X | M21: =Tippa!G39 -> 1 | N21: =Tippa!H39 -> 1
A22: Panama
A23: Peru | C23: Grupp C | D23: 1X2 | E23: P | F23: Resultat | H23: P | J23: Bonus | L23: 1X2 | M23: Resultat
A24: Polen | C24: =Tippa!C45 -> Argentina - Saudiarabien | D24: =IF(F24="*","*",IF(F24>G24,1,IF(F24=G24,"X",IF(F24<G24,2,"error")))) -> * | E24: =(L24=D24)*$A$73 -> 0 | F24: * | G24: * | H24: =(F24=M24)*(G24=N24)*$A$77 -> 0 | J24: =+IF(SUM(H24:H29)=$A$77*6,$A$78,0) -> 0 | L24: =Tippa!F45 -> 1 | M24: =Tippa!G45 -> 4 | N24: =Tippa!H45 -> 0
A25: Portugal | C25: =Tippa!C46 -> Mexiko - Polen | D25: =IF(F25="*","*",IF(F25>G25,1,IF(F25=G25,"X",IF(F25<G25,2,"error")))) -> * | E25: =(L25=D25)*$A$73 -> 0 | F25: * | G25: * | H25: =(F25=M25)*(G25=N25)*$A$77 -> 0 | J25: =IF(SUM(E24:E29)=$A$73*6,$A$74,0) -> 0 | L25: =Tippa!F46 -> 1 | M25: =Tippa!G46 -> 2 | N25: =Tippa!H46 -> 1
A26: Ryssland | C26: =Tippa!C47 -> Polen - Saudiarabien | D26: =IF(F26="*","*",IF(F26>G26,1,IF(F26=G26,"X",IF(F26<G26,2,"error")))) -> * | E26: =(L26=D26)*$A$73 -> 0 | F26: * | G26: * | H26: =(F26=M26)*(G26=N26)*$A$77 -> 0 | L26: =Tippa!F47 -> 1 | M26: =Tippa!G47 -> 1 | N26: =Tippa!H47 -> 0
A27: Saudiarabien | C27: =Tippa!C48 -> Argentina - Mexiko | D27: =IF(F27="*","*",IF(F27>G27,1,IF(F27=G27,"X",IF(F27<G27,2,"error")))) -> * | E27: =(L27=D27)*$A$73 -> 0 | F27: * | G27: * | H27: =(F27=M27)*(G27=N27)*$A$77 -> 0 | L27: =Tippa!F48 -> X | M27: =Tippa!G48 -> 2 | N27: =Tippa!H48 -> 2
A28: Schweiz | C28: =Tippa!C49 -> Saudiarabien - Mexiko | D28: =IF(F28="*","*",IF(F28>G28,1,IF(F28=G28,"X",IF(F28<G28,2,"error")))) -> * | E28: =(L28=D28)*$A$73 -> 0 | F28: * | G28: * | H28: =(F28=M28)*(G28=N28)*$A$77 -> 0 | L28: =Tippa!F49 -> 2 | M28: =Tippa!G49 -> 0 | N28: =Tippa!H49 -> 2
A29: Senegal | C29: =Tippa!C50 -> Polen - Argentina | D29: =IF(F29="*","*",IF(F29>G29,1,IF(F29=G29,"X",IF(F29<G29,2,"error")))) -> * | E29: =(L29=D29)*$A$73 -> 0 | F29: * | G29: * | H29: =(F29=M29)*(G29=N29)*$A$77 -> 0 | L29: =Tippa!F50 -> 2 | M29: =Tippa!G50 -> 1 | N29: =Tippa!H50 -> 2
A30: Serbien
A31: Spanien | C31: Grupp D | D31: 1X2 | E31: P | F31: Resultat | H31: P | J31: Bonus | L31: 1X2 | M31: Resultat
A32: Sverige | C32: =Tippa!C56 -> Frankrike - Australien | D32: =IF(F32="*","*",IF(F32>G32,1,IF(F32=G32,"X",IF(F32<G32,2,"error")))) -> * | E32: =(L32=D32)*$A$73 -> 0 | F32: * | G32: * | H32: =(F32=M32)*(G32=N32)*$A$77 -> 0 | J32: =+IF(SUM(H32:H37)=$A$77*6,$A$78,0) -> 0 | L32: =Tippa!F56 -> 1 | M32: =Tippa!G56 -> 4 | N32: =Tippa!H56 -> 0
A33: Sydkorea | C33: =Tippa!C57 -> Danmark - Tunisien | D33: =IF(F33="*","*",IF(F33>G33,1,IF(F33=G33,"X",IF(F33<G33,2,"error")))) -> * | E33: =(L33=D33)*$A$73 -> 0 | F33: * | G33: * | H33: =(F33=M33)*(G33=N33)*$A$77 -> 0 | J33: =IF(SUM(E32:E37)=$A$73*6,$A$74,0) -> 0 | L33: =Tippa!F57 -> 1 | M33: =Tippa!G57 -> 2 | N33: =Tippa!H57 -> 1
A34: Tunisien | C34: =Tippa!C58 -> Frankrike - Danmark | D34: =IF(F34="*","*",IF(F34>G34,1,IF(F34=G34,"X",IF(F34<G34,2,"error")))) -> * | E34: =(L34=D34)*$A$73 -> 0 | F34: * | G34: * | H34: =(F34=M34)*(G34=N34)*$A$77 -> 0 | L34: =Tippa!F58 -> 1 | M34: =Tippa!G58 -> 1 | N34: =Tippa!H58 -> 0
A35: Tyskland | C35: =Tippa!C59 -> Tunisien - Australien | D35: =IF(F35="*","*",IF(F35>G35,1,IF(F35=G35,"X",IF(F35<G35,2,"error")))) -> * | E35: =(L35=D35)*$A$73 -> 0 | F35: * | G35: * | H35: =(F35=M35)*(G35=N35)*$A$77 -> 0 | L35: =Tippa!F59 -> X | M35: =Tippa!G59 -> 1 | N35: =Tippa!H59 -> 1
A36: Uruguay | C36: =Tippa!C60 -> Australien - Danmark | D36: =IF(F36="*","*",IF(F36>G36,1,IF(F36=G36,"X",IF(F36<G36,2,"error")))) -> * | E36: =(L36=D36)*$A$73 -> 0 | F36: * | G36: * | H36: =(F36=M36)*(G36=N36)*$A$77 -> 0 | L36: =Tippa!F60 -> 2 | M36: =Tippa!G60 -> 0 | N36: =Tippa!H60 -> 3
C37: =Tippa!C61 -> Tunisien - Frankrike | D37: =IF(F37="*","*",IF(F37>G37,1,IF(F37=G37,"X",IF(F37<G37,2,"error")))) -> * | E37: =(L37=D37)*$A$73 -> 0 | F37: * | G37: * | H37: =(F37=M37)*(G37=N37)*$A$77 -> 0 | L37: =Tippa!F61 -> 2 | M37: =Tippa!G61 -> 0 | N37: =Tippa!H61 -> 2
C39: Grupp E | D39: 1X2 | E39: P | F39: Resultat | H39: P | J39: Bonus | L39: 1X2 | M39: Resultat
C40: =Tippa!C67 -> Tyskland - Japan | D40: =IF(F40="*","*",IF(F40>G40,1,IF(F40=G40,"X",IF(F40<G40,2,"error")))) -> * | E40: =(L40=D40)*$A$73 -> 0 | F40: * | G40: * | H40: =(F40=M40)*(G40=N40)*$A$77 -> 0 | J40: =+IF(SUM(H40:H45)=$A$77*6,$A$78,0) -> 0 | L40: =Tippa!F67 -> 1 | M40: =Tippa!G67 -> 3 | N40: =Tippa!H67 -> 1
C41: =Tippa!C68 -> Spanien - Costa Rica | D41: =IF(F41="*","*",IF(F41>G41,1,IF(F41=G41,"X",IF(F41<G41,2,"error")))) -> * | E41: =(L41=D41)*$A$73 -> 0 | F41: * | G41: * | H41: =(F41=M41)*(G41=N41)*$A$77 -> 0 | J41: =IF(SUM(E40:E45)=$A$73*6,$A$74,0) -> 0 | L41: =Tippa!F68 -> 1 | M41: =Tippa!G68 -> 3 | N41: =Tippa!H68 -> 1
C42: =Tippa!C69 -> Japan - Costa Rica | D42: =IF(F42="*","*",IF(F42>G42,1,IF(F42=G42,"X",IF(F42<G42,2,"error")))) -> * | E42: =(L42=D42)*$A$73 -> 0 | F42: * | G42: * | H42: =(F42=M42)*(G42=N42)*$A$77 -> 0 | L42: =Tippa!F69 -> 1 | M42: =Tippa!G69 -> 1 | N42: =Tippa!H69 -> 0
...

Sheet Kolla
C2: ="Sammanfattning VM Tips: "&Tippa!C3 -> Sammanfattning VM Tips: Mitt Namn: Jonathan Behr Mattsson | J2: =Tippa!D3 -> Alla kontroller i arket Tippa är OK
C4: Moment | G4: Dina poäng | J4: Check
C5: A: Match och resultat | G5: =SUM(D28:E29,H28:I29,L28:M29,P28:Q29,D43:E44,H43:I44,L43:M44,P43:Q44) -> 0 | J5: =IF(ABS(G5-Rätta!G226)>0.01,1,0) -> 0
C6: B: Placeringar i gruppen | G6: =SUM(D30:E30,H30:I30,L30:M30,P30:Q30,D45:E45,H45:I45,L45:M45,P45:Q45) -> 0 | J6: =IF(ABS(G6-Rätta!G227)>0.01,1,0) -> 0
C7: C: Lag till åttondelsfinal | G7: =E86 -> 0 | J7: =IF(ABS(G7-Rätta!G228)>0.01,1,0) -> 0
C8: D: Lag i kvartsfinal | G8: =E87 -> 0 | J8: =IF(ABS(G8-Rätta!G229)>0.01,1,0) -> 0
C9: E: Lag i semifinal | G9: =E88 -> 0 | J9: =IF(ABS(G9-Rätta!G230)>0.01,1,0) -> 0
C10: F: Placeringar 1-4 | G10: =E89 -> 0 | J10: =IF(ABS(G10-Rätta!G231)>0.01,1,0) -> 0
C11: G: Top 3 skytteliga | G11: =H89 -> 0 | J11: =IF(ABS(G11-Rätta!G232)>0.01,1,0) -> 0
C12: H: Första målskytt | G12: =H92 -> 0 | J12: =IF(ABS(G12-Rätta!G233)>0.01,1,0) -> 0
C13: I: Lag som får första röda kort | G13: =L87 -> 0 | J13: =IF(ABS(G13-Rätta!G234)>0.01,1,0) -> 0
C14: J: Lag som gör första målet | G14: =P87 -> 0 | J14: =IF(ABS(G14-Rätta!G235)>0.01,1,0) -> 0
C15: TOTALT | G15: =SUM(G5:G14) -> 0 | J15: =IF(ABS(G15-Rätta!G236)>0.01,1,0) -> 0
C18: Gruppspelet
C20: Grupp A | D20: Placering | G20: Grupp B | H20: Placering | K20: Grupp C | L20: Placering | O20: Grupp D | P20: Placering
C21: Land | D21: Ditt tips | E21: Poäng | G21: Land | H21: Ditt tips | I21: Poäng | K21: Land | L21: Ditt tips | M21: Poäng | O21: Land | P21: Ditt tips | Q21: Poäng
D22: =Beräkningar!AO4 -> 4 | E22: =Rätta!E78 -> 0 | H22: =Beräkningar!AO9 -> 1 | I22: =Rätta!E84 -> 0 | L22: =Beräkningar!AO14 -> 1 | M22: =Rätta!E90 -> 0 | P22: =Beräkningar!AO19 -> 1 | Q22: =Rätta!E96 -> 0
D23: =Beräkningar!AO5 -> 3 | E23: =Rätta!E79 -> 0 | H23: =Beräkningar!AO10 -> 4 | I23: =Rätta!E85 -> 0 | L23: =Beräkningar!AO15 -> 4 | M23: =Rätta!E91 -> 0 | P23: =Beräkningar!AO20 -> 4 | Q23: =Rätta!E97 -> 0
D24: =Beräkningar!AO6 -> 2 | E24: =Rätta!E80 -> 0 | H24: =Beräkningar!AO11 -> 2 | I24: =Rätta!E86 -> 0 | L24: =Beräkningar!AO16 -> 2 | M24: =Rätta!E92 -> 0 | P24: =Beräkningar!AO21 -> 2 | Q24: =Rätta!E98 -> 0
D25: =Beräkningar!AO7 -> 1 | E25: =Rätta!E81 -> 0 | H25: =Beräkningar!AO12 -> 3 | I25: =Rätta!E87 -> 0 | L25: =Beräkningar!AO17 -> 3 | M25: =Rätta!E93 -> 0 | P25: =Beräkningar!AO22 -> 3 | Q25: =Rätta!E99 -> 0
C27: Grupp A | D27: Poäng | E27: Bonus | G27: Grupp B | H27: Poäng | I27: Bonus | K27: Grupp C | L27: Poäng | M27: Bonus | O27: Grupp D | P27: Poäng | Q27: Bonus
C28: Resultat | D28: =SUM(Rätta!H8:H13) -> 0 | E28: =Rätta!J8 -> 0 | G28: Resultat | H28: =SUM(Rätta!H16:H21) -> 0 | I28: =Rätta!J16 -> 0 | K28: Resultat | L28: =SUM(Rätta!H24:H29) -> 0 | M28: =Rätta!J24 -> 0 | O28: Resultat | P28: =SUM(Rätta!H32:H37) -> 0 | Q28: =Rätta!J32 -> 0
C29: 1,X,2 | D29: =SUM(Rätta!E8:E13) -> 0 | E29: =Rätta!J9 -> 0 | G29: 1,X,2 | H29: =SUM(Rätta!E16:E21) -> 0 | I29: =Rätta!J17 -> 0 | K29: 1,X,2 | L29: =SUM(Rätta!E24:E29) -> 0 | M29: =Rätta!J25 -> 0 | O29: 1,X,2 | P29: =SUM(Rätta!E32:E37) -> 0 | Q29: =Rätta!J33 -> 0
C30: Placeringsbonus | D30: =SUM(E22:E25) -> 0 | E30: =Rätta!J78 -> 0 | G30: Placeringsbonus | H30: =SUM(I22:I25) -> 0 | I30: =Rätta!J84 -> 0 | K30: Placeringsbonus | L30: =SUM(M22:M25) -> 0 | M30: =Rätta!J90 -> 0 | O30: Placeringsbonus | P30: =SUM(Q22:Q25) -> 0 | Q30: =Rätta!J96 -> 0
C32: Totalt Grupp A | D32: =SUM(D28:E30) -> 0 | G32: Totalt Grupp B | H32: =SUM(H28:I30) -> 0 | K32: Totalt Grupp C | L32: =SUM(L28:M30) -> 0 | O32: Totalt Grupp D | P32: =SUM(P28:Q30) -> 0
C35: Grupp E | D35: Placering | G35: Grupp F | H35: Placering | K35: Grupp G | L35: Placering | O35: Grupp H | P35: Placering
C36: Land | D36: Ditt tips | E36: Poäng | G36: Land | H36: Ditt tips | I36: Poäng | K36: Land | L36: Ditt tips | M36: Poäng | O36: Land | P36: Ditt tips | Q36: Poäng
D37: =Beräkningar!AO24 -> 2 | E37: =Rätta!E102 -> 0 | H37: =Beräkningar!AO29 -> 1 | I37: =Rätta!E108 -> 0 | L37: =Beräkningar!AO34 -> 1 | M37: =Rätta!E114 -> 0 | P37: =Beräkningar!AO39 -> 1 | Q37: =Rätta!E120 -> 0
D38: =Beräkningar!AO25 -> 4 | E38: =Rätta!E103 -> 0 | H38: =Beräkningar!AO30 -> 4 | I38: =Rätta!E109 -> 0 | L38: =Beräkningar!AO35 -> 4 | M38: =Rätta!E115 -> 0 | P38: =Beräkningar!AO40 -> 3 | Q38: =Rätta!E121 -> 0
D39: =Beräkningar!AO26 -> 1 | E39: =Rätta!E104 -> 0 | H39: =Beräkningar!AO31 -> 3 | I39: =Rätta!E110 -> 0 | L39: =Beräkningar!AO36 -> 3 | M39: =Rätta!E116 -> 0 | P39: =Beräkningar!AO41 -> 2 | Q39: =Rätta!E122 -> 0
D40: =Beräkningar!AO27 -> 3 | E40: =Rätta!E105 -> 0 | H40: =Beräkningar!AO32 -> 2 | I40: =Rätta!E111 -> 0 | L40: =Beräkningar!AO37 -> 2 | M40: =Rätta!E117 -> 0 | P40: =Beräkningar!AO42 -> 4 | Q40: =Rätta!E123 -> 0
C42: Grupp E | D42: Poäng | E42: Bonus | G42: Grupp F | H42: Poäng | I42: Bonus | K42: Grupp G | L42: Poäng | M42: Bonus | O42: Grupp H | P42: Poäng | Q42: Bonus
C43: Resultat | D43: =SUM(Rätta!H40:H45) -> 0 | E43: =Rätta!J40 -> 0 | G43: Resultat | H43: =SUM(Rätta!H48:H53) -> 0 | I43: =Rätta!J48 -> 0 | K43: Resultat | L43: =SUM(Rätta!H56:H61) -> 0 | M43: =Rätta!J56 -> 0 | O43: Resultat | P43: =SUM(Rätta!H64:H69) -> 0 | Q43: =Rätta!J64 -> 0
C44: 1,X,2 | D44: =SUM(Rätta!E40:E45) -> 0 | E44: =Rätta!J41 -> 0 | G44: 1,X,2 | H44: =SUM(Rätta!E48:E53) -> 0 | I44: =Rätta!J49 -> 0 | K44: 1,X,2 | L44: =SUM(Rätta!E56:E61) -> 0 | M44: =Rätta!J57 -> 0 | O44: 1,X,2 | P44: =SUM(Rätta!E64:E69) -> 0 | Q44: =Rätta!J65 -> 0
C45: Placering | D45: =SUM(E37:E40) -> 0 | E45: =Rätta!J102 -> 0 | G45: Placeringsbonus | H45: =SUM(I37:I40) -> 0 | I45: =Rätta!J108 -> 0 | K45: Placeringsbonus | L45: =SUM(M37:M40) -> 0 | M45: =Rätta!J114 -> 0 | O45: Placeringsbonus | P45: =SUM(Q37:Q40) -> 0 | Q45: =Rätta!J120 -> 0
C47: Totalt Grupp E | D47: =SUM(D43:E45) -> 0 | G47: Totalt Grupp F | H47: =SUM(H43:I45) -> 0 | K47: Totalt Grupp G | L47: =SUM(L43:M45) -> 0 | O47: Totalt Grupp H | P47: =SUM(P43:Q45) -> 0
C50: Slutspelet - Ditt tips
C84: Slutspelet | D84: Placering | G84: Målskyttar | K84: Röda kortet | O84: Straffen
C85: Moment | D85: # Rätt | E85: Poäng
C86: Åttondel | D86: =COUNTIF(Rätta!$E$132:$E$147,Rätta!$A$106) -> 0 | E86: =Rätta!E149+Rätta!J149 -> 0 | G86: =Tippa!P66 -> Mbappé | H86: << 1:a Skytteliga | K86: =Tippa!P52 -> Tunisien | O86: =Tippa!P59 -> Qatar
...

Sheet Beräkningar
AF2: Tabeller
B3: Spelschema | N3: Fyll u grupperna | P3: Poäng | Q3: + mål | R3: - mål | S3: +- mål | T3: Ranking 1 | U3: Ranking 2 | V3: Ranking 3 | W3: Ranking random | X3: Ranking 2 | AA3: Ranking 3 | AD3: Slutrank | AF3: Placering | AG3: Lag | AH3: Poäng | AI3: +- mål | AJ3: + mål | AL3: Kontroll | AM3: Plac | AN3: Kod | AO3: Ditt tips
B4: Sön 20/11 | C4: 0.70833333 | D4: A1-A2 | E4: =LEFT(D4,2) -> A1 | F4: =RIGHT(D4,2) -> A2 | G4: =INDEX($N$4:$N$42,MATCH(E4,$M$4:$M$42,0)) -> Qatar | H4: =INDEX($N$4:$N$42,MATCH(F4,$M$4:$M$42,0)) -> Ecuador | I4: =LEFT(D4,1) -> A | J4: =COUNTIF($I$4:I4,I4) -> 1 | K4: =I4&J4 -> A1 | M4: A1 | N4: Qatar | P4: =SUMIF($AR$5:$AR$10,N4,$AV$5:$AV$10)+SUMIF($AS$5:$AS$10,N4,$AW$5:$AW$10) -> 1 | Q4: =SUMIF($AR$5:$AR$10,N4,$AT$5:$AT$10)+SUMIF($AS$5:$AS$10,N4,$AU$5:$AU$10) -> 1 | R4: =-SUMIF($AR$5:$AR$10,N4,$AU$5:$AU$10)-SUMIF($AS$5:$AS$10,N4,$AT$5:$AT$10) -> -6 | S4: =SUM(Q4:R4) -> -5 | T4: =RANK(P4,$P$4:$P$7,0) -> 3 | U4: =RANK(S4,$S$4:$S$7,0) -> 4 | V4: =RANK(Q4,$Q$4:$Q$7,0) -> 3 | W4: 0.001 | X4: =IF(COUNTIF($T$4:$T$7,T4)>1,U4,0) -> 4 | Y4: =IF(X4=MAX($X$4:$X$7),0.2,0) -> 0.2 | Z4: =Y4+T4 -> 3.2 | AA4: =IF(COUNTIF($Z$4:$Z$7,Z4)>1,V4,0) -> 0 | AB4: =IF(AA4=MAX($AA$4:$AA$7),0.1,0) -> 0.1 | AC4: =Z4+AB4+W4 -> 3.301 | AD4: =_xlfn.RANK.EQ(AC4,$AC$4:$AC$7,1) -> 4 | AF4: 1 | AG4: =INDEX($N$4:$N$7,MATCH($AF4,$AD$4:$AD$7,0),) -> Nederländerna | AH4: =INDEX($P$4:$P$7,MATCH($AF4,$AD$4:$AD$7,0),) -> 9 | AI4: =INDEX($S$4:$S$7,MATCH($AF4,$AD$4:$AD$7,0),) -> 6 | AJ4: =INDEX($Q$4:$Q$7,MATCH($AF4,$AD$4:$AD$7,0),) -> 6 | AL4: =COUNTIF(Tippa!$J$23:$J$26,Beräkningar!AF4) -> 1 | AM4: =Tippa!J23 -> 1 | AN4: =AM4&"A" -> 1A | AO4: =INDEX(AM4:AM7,MATCH(N4,AG4:AG7,0),) -> 4 | AQ4: Grupp A | AT4: Resultat | AV4: Poäng | AY4: Hur bör man ranka lagen | AZ4: Vad gör vi?
B5: Mån 21/11 | C5: 0.70833333 | D5: A3-A4 | E5: =LEFT(D5,2) -> A3 | F5: =RIGHT(D5,2) -> A4 | G5: =INDEX($N$4:$N$42,MATCH(E5,$M$4:$M$42,0)) -> Senegal | H5: =INDEX($N$4:$N$42,MATCH(F5,$M$4:$M$42,0)) -> Nederländerna | I5: =LEFT(D5,1) -> A | J5: =COUNTIF($I$4:I5,I5) -> 2 | K5: =I5&J5 -> A2 | M5: A2 | N5: Ecuador | P5: =SUMIF($AR$5:$AR$10,N5,$AV$5:$AV$10)+SUMIF($AS$5:$AS$10,N5,$AW$5:$AW$10) -> 1 | Q5: =SUMIF($AR$5:$AR$10,N5,$AT$5:$AT$10)+SUMIF($AS$5:$AS$10,N5,$AU$5:$AU$10) -> 1 | R5: =-SUMIF($AR$5:$AR$10,N5,$AU$5:$AU$10)-SUMIF($AS$5:$AS$10,N5,$AT$5:$AT$10) -> -3 | S5: =SUM(Q5:R5) -> -2 | T5: =RANK(P5,$P$4:$P$7,0) -> 3 | U5: =RANK(S5,$S$4:$S$7,0) -> 3 | V5: =RANK(Q5,$Q$4:$Q$7,0) -> 3 | W5: =W4+0.001 -> 0.002 | X5: =IF(COUNTIF($T$4:$T$7,T5)>1,U5,0) -> 3 | Y5: =IF(X5=MAX($X$4:$X$7),0.2,0) -> 0 | Z5: =Y5+T5 -> 3 | AA5: =IF(COUNTIF($Z$4:$Z$7,Z5)>1,V5,0) -> 0 | AB5: =IF(AA5=MAX($AA$4:$AA$7),0.1,0) -> 0.1 | AC5: =Z5+AB5+W5 -> 3.102 | AD5: =_xlfn.RANK.EQ(AC5,$AC$4:$AC$7,1) -> 3 | AF5: 2 | AG5: =INDEX($N$4:$N$7,MATCH($AF5,$AD$4:$AD$7,0),) -> Senegal | AH5: =INDEX($P$4:$P$7,MATCH($AF5,$AD$4:$AD$7,0),) -> 6 | AI5: =INDEX($S$4:$S$7,MATCH($AF5,$AD$4:$AD$7,0),) -> 1 | AJ5: =INDEX($Q$4:$Q$7,MATCH($AF5,$AD$4:$AD$7,0),) -> 3 | AL5: =COUNTIF(Tippa!$J$23:$J$26,Beräkningar!AF5) -> 1 | AM5: =Tippa!J24 -> 2 | AN5: =AM5&"A" -> 2A | AO5: =INDEX(AM4:AM7,MATCH(N5,AG4:AG7,0),) -> 3 | AP5: =Tippa!A23 -> A1 | AQ5: =Tippa!C23 -> Qatar - Ecuador | AR5: =INDEX($G$4:$G$51,MATCH(AP5,$K$4:$K$51,0),) -> Qatar | AS5: =INDEX($H$4:$H$51,MATCH(AP5,$K$4:$K$51,0),) -> Ecuador | AT5: =Tippa!G23 -> 1 | AU5: =Tippa!H23 -> 1 | AV5: =IF(AT5="-",0,IF(AT5>AU5,3,IF(AT5=AU5,1,0))) -> 1 | AW5: =IF(AT5="-",0,IF(AU5>AT5,3,IF(AU5=AT5,1,0))) -> 1 | AY5: 1. Poängen i alla gruppmatcher, med 3 poäng vid vinst, 1 poäng vid oavgjort och 0 poäng vid förlust. | AZ5: OK
B6: Mån 21/11 | C6: 0.83333333 | D6: B3-B4 | E6: =LEFT(D6,2) -> B3 | F6: =RIGHT(D6,2) -> B4 | G6: =INDEX($N$4:$N$42,MATCH(E6,$M$4:$M$42,0)) -> USA | H6: =INDEX($N$4:$N$42,MATCH(F6,$M$4:$M$42,0)) -> Wales | I6: =LEFT(D6,1) -> B | J6: =COUNTIF($I$4:I6,I6) -> 1 | K6: =I6&J6 -> B1 | M6: A3 | N6: Senegal | P6: =SUMIF($AR$5:$AR$10,N6,$AV$5:$AV$10)+SUMIF($AS$5:$AS$10,N6,$AW$5:$AW$10) -> 6 | Q6: =SUMIF($AR$5:$AR$10,N6,$AT$5:$AT$10)+SUMIF($AS$5:$AS$10,N6,$AU$5:$AU$10) -> 3 | R6: =-SUMIF($AR$5:$AR$10,N6,$AU$5:$AU$10)-SUMIF($AS$5:$AS$10,N6,$AT$5:$AT$10) -> -2 | S6: =SUM(Q6:R6) -> 1 | T6: =RANK(P6,$P$4:$P$7,0) -> 2 | U6: =RANK(S6,$S$4:$S$7,0) -> 2 | V6: =RANK(Q6,$Q$4:$Q$7,0) -> 2 | W6: =W5+0.001 -> 0.003 | X6: =IF(COUNTIF($T$4:$T$7,T6)>1,U6,0) -> 0 | Y6: =IF(X6=MAX($X$4:$X$7),0.2,0) -> 0 | Z6: =Y6+T6 -> 2 | AA6: =IF(COUNTIF($Z$4:$Z$7,Z6)>1,V6,0) -> 0 | AB6: =IF(AA6=MAX($AA$4:$AA$7),0.1,0) -> 0.1 | AC6: =Z6+AB6+W6 -> 2.103 | AD6: =_xlfn.RANK.EQ(AC6,$AC$4:$AC$7,1) -> 2 | AF6: 3 | AG6: =INDEX($N$4:$N$7,MATCH($AF6,$AD$4:$AD$7,0),) -> Ecuador | AH6: =INDEX($P$4:$P$7,MATCH($AF6,$AD$4:$AD$7,0),) -> 1 | AI6: =INDEX($S$4:$S$7,MATCH($AF6,$AD$4:$AD$7,0),) -> -2 | AJ6: =INDEX($Q$4:$Q$7,MATCH($AF6,$AD$4:$AD$7,0),) -> 1 | AL6: =COUNTIF(Tippa!$J$23:$J$26,Beräkningar!AF6) -> 1 | AM6: =Tippa!J25 -> 3 | AN6: =AM6&"A" -> 3A | AO6: =INDEX(AM4:AM7,MATCH(N6,AG4:AG7,0),) -> 2 | AP6: =Tippa!A24 -> A2 | AQ6: =Tippa!C24 -> Senegal - Nederländerna | AR6: =INDEX($G$4:$G$51,MATCH(AP6,$K$4:$K$51,0),) -> Senegal | AS6: =INDEX($H$4:$H$51,MATCH(AP6,$K$4:$K$51,0),) -> Nederländerna | AT6: =Tippa!G24 -> 0 | AU6: =Tippa!H24 -> 2 | AV6: =IF(AT6="-",0,IF(AT6>AU6,3,IF(AT6=AU6,1,0))) -> 0 | AW6: =IF(AT6="-",0,IF(AU6>AT6,3,IF(AU6=AT6,1,0))) -> 3 | AY6: 2. Målskillnad i alla gruppmatcher | AZ6: OK
B7: Mån 21/11 | C7: 0.58333333 | D7: B1-B2 | E7: =LEFT(D7,2) -> B1 | F7: =RIGHT(D7,2) -> B2 | G7: =INDEX($N$4:$N$42,MATCH(E7,$M$4:$M$42,0)) -> England | H7: =INDEX($N$4:$N$42,MATCH(F7,$M$4:$M$42,0)) -> Iran | I7: =LEFT(D7,1) -> B | J7: =COUNTIF($I$4:I7,I7) -> 2 | K7: =I7&J7 -> B2 | M7: A4 | N7: Nederländerna | P7: =SUMIF($AR$5:$AR$10,N7,$AV$5:$AV$10)+SUMIF($AS$5:$AS$10,N7,$AW$5:$AW$10) -> 9 | Q7: =SUMIF($AR$5:$AR$10,N7,$AT$5:$AT$10)+SUMIF($AS$5:$AS$10,N7,$AU$5:$AU$10) -> 6 | R7: =-SUMIF($AR$5:$AR$10,N7,$AU$5:$AU$10)-SUMIF($AS$5:$AS$10,N7,$AT$5:$AT$10) -> 0 | S7: =SUM(Q7:R7) -> 6 | T7: =RANK(P7,$P$4:$P$7,0) -> 1 | U7: =RANK(S7,$S$4:$S$7,0) -> 1 | V7: =RANK(Q7,$Q$4:$Q$7,0) -> 1 | W7: =W6+0.001 -> 0.004 | X7: =IF(COUNTIF($T$4:$T$7,T7)>1,U7,0) -> 0 | Y7: =IF(X7=MAX($X$4:$X$7),0.2,0) -> 0 | Z7: =Y7+T7 -> 1 | AA7: =IF(COUNTIF($Z$4:$Z$7,Z7)>1,V7,0) -> 0 | AB7: =IF(AA7=MAX($AA$4:$AA$7),0.1,0) -> 0.1 | AC7: =Z7+AB7+W7 -> 1.104 | AD7: =_xlfn.RANK.EQ(AC7,$AC$4:$AC$7,1) -> 1 | AF7: 4 | AG7: =INDEX($N$4:$N$7,MATCH($AF7,$AD$4:$AD$7,0),) -> Qatar | AH7: =INDEX($P$4:$P$7,MATCH($AF7,$AD$4:$AD$7,0),) -> 1 | AI7: =INDEX($S$4:$S$7,MATCH($AF7,$AD$4:$AD$7,0),) -> -5 | AJ7: =INDEX($Q$4:$Q$7,MATCH($AF7,$AD$4:$AD$7,0),) -> 1 | AL7: =COUNTIF(Tippa!$J$23:$J$26,Beräkningar!AF7) -> 1 | AM7: =Tippa!J26 -> 4 | AN7: =AM7&"A" -> 4A | AO7: =INDEX(AM4:AM7,MATCH(N7,AG4:AG7,0),) -> 1 | AP7: =Tippa!A25 -> A3 | AQ7: =Tippa!C25 -> Qatar - Senegal | AR7: =INDEX($G$4:$G$51,MATCH(AP7,$K$4:$K$51,0),) -> Qatar | AS7: =INDEX($H$4:$H$51,MATCH(AP7,$K$4:$K$51,0),) -> Senegal | AT7: =Tippa!G25 -> 0 | AU7: =Tippa!H25 -> 2 | AV7: =IF(AT7="-",0,IF(AT7>AU7,3,IF(AT7=AU7,1,0))) -> 0 | AW7: =IF(AT7="-",0,IF(AU7>AT7,3,IF(AU7=AT7,1,0))) -> 3 | AY7: 3. Gjorda mål i alla gruppmatcher | AZ7: OK
B8: Tis 22/11 | C8: 0.45833333 | D8: C1-C2 | E8: =LEFT(D8,2) -> C1 | F8: =RIGHT(D8,2) -> C2 | G8: =INDEX($N$4:$N$42,MATCH(E8,$M$4:$M$42,0)) -> Argentina | H8: =INDEX($N$4:$N$42,MATCH(F8,$M$4:$M$42,0)) -> Saudiarabien | I8: =LEFT(D8,1) -> C | J8: =COUNTIF($I$4:I8,I8) -> 1 | K8: =I8&J8 -> C1 | AP8: =Tippa!A26 -> A4 | AQ8: =Tippa!C26 -> Nederländerna - Ecuador | AR8: =INDEX($G$4:$G$51,MATCH(AP8,$K$4:$K$51,0),) -> Nederländerna | AS8: =INDEX($H$4:$H$51,MATCH(AP8,$K$4:$K$51,0),) -> Ecuador | AT8: =Tippa!G26 -> 1 | AU8: =Tippa!H26 -> 0 | AV8: =IF(AT8="-",0,IF(AT8>AU8,3,IF(AT8=AU8,1,0))) -> 3 | AW8: =IF(AT8="-",0,IF(AU8>AT8,3,IF(AU8=AT8,1,0))) -> 0 | AY8: 4. Poäng i matcherna mellan likaplacerade lag | AZ8: EJ OK | BA8: Random härifrån och ned
B9: Tis 22/11 | C9: 0.83333333 | D9: D1-D2 | E9: =LEFT(D9,2) -> D1 | F9: =RIGHT(D9,2) -> D2 | G9: =INDEX($N$4:$N$42,MATCH(E9,$M$4:$M$42,0)) -> Frankrike | H9: =INDEX($N$4:$N$42,MATCH(F9,$M$4:$M$42,0)) -> Australien | I9: =LEFT(D9,1) -> D | J9: =COUNTIF($I$4:I9,I9) -> 1 | K9: =I9&J9 -> D1 | M9: B1 | N9: England | P9: =SUMIF($AR$13:$AR$18,N9,$AV$13:$AV$18)+SUMIF($AS$13:$AS$18,N9,$AW$13:$AW$18) -> 5 | Q9: =SUMIF($AR$13:$AR$18,N9,$AT$13:$AT$18)+SUMIF($AS$13:$AS$18,N9,$AU$13:$AU$18) -> 7 | R9: =-SUMIF($AR$13:$AR$18,N9,$AU$13:$AU$18)-SUMIF($AS$13:$AS$18,N9,$AT$13:$AT$18) -> -3 | S9: =SUM(Q9:R9) -> 4 | T9: =RANK(P9,$P$9:$P$12,0) -> 1 | U9: =RANK(S9,$S$9:$S$12,0) -> 1 | V9: =RANK(Q9,$Q$9:$Q$12,0) -> 1 | W9: 0.001 | X9: =IF(COUNTIF($T$9:$T$12,T9)>1,U9,0) -> 1 | Y9: =IF(X9=MAX($X$9:$X$12),0.2,0) -> 0 | Z9: =Y9+T9 -> 1 | AA9: =IF(COUNTIF($Z$9:$Z$12,Z9)>1,V9,0) -> 0 | AB9: =IF(AA9=MAX($AA$9:$AA$12),0.1,0) -> 0 | AC9: =Z9+AB9+W9 -> 1.001 | AD9: =_xlfn.RANK.EQ(AC9,$AC$9:$AC$12,1) -> 1 | AF9: 1 | AG9: =INDEX($N$9:$N$12,MATCH($AF9,$AD$9:$AD$12,0),) -> England | AH9: =INDEX($P$9:$P$12,MATCH($AF9,$AD$9:$AD$12,0),) -> 5 | AI9: =INDEX($S$9:$S$12,MATCH($AF9,$AD$9:$AD$12,0),) -> 4 | AJ9: =INDEX($Q$9:$Q$12,MATCH($AF9,$AD$9:$AD$12,0),) -> 7 | AL9: =COUNTIF(Tippa!$J$34:$J$37,Beräkningar!AF9) -> 1 | AM9: =Tippa!J34 -> 1 | AN9: =AM9&"B" -> 1B | AO9: =INDEX(AM9:AM12,MATCH(N9,AG9:AG12,0),) -> 1 | AP9: =Tippa!A27 -> A5 | AQ9: =Tippa!C27 -> Ecuador - Senegal | AR9: =INDEX($G$4:$G$51,MATCH(AP9,$K$4:$K$51,0),) -> Ecuador | AS9: =INDEX($H$4:$H$51,MATCH(AP9,$K$4:$K$51,0),) -> Senegal | AT9: =Tippa!G27 -> 0 | AU9: =Tippa!H27 -> 1 | AV9: =IF(AT9="-",0,IF(AT9>AU9,3,IF(AT9=AU9,1,0))) -> 0 | AW9: =IF(AT9="-",0,IF(AU9>AT9,3,IF(AU9=AT9,1,0))) -> 3 | AY9: 5. Målskillnad i matcherna mellan likaplacerade lag | AZ9: EJ OK
B10: Tis 22/11 | C10: 0.70833333 | D10: C3-C4 | E10: =LEFT(D10,2) -> C3 | F10: =RIGHT(D10,2) -> C4 | G10: =INDEX($N$4:$N$42,MATCH(E10,$M$4:$M$42,0)) -> Mexiko | H10: =INDEX($N$4:$N$42,MATCH(F10,$M$4:$M$42,0)) -> Polen | I10: =LEFT(D10,1) -> C | J10: =COUNTIF($I$4:I10,I10) -> 2 | K10: =I10&J10 -> C2 | M10: B2 | N10: Iran | P10: =SUMIF($AR$13:$AR$18,N10,$AV$13:$AV$18)+SUMIF($AS$13:$AS$18,N10,$AW$13:$AW$18) -> 0 | Q10: =SUMIF($AR$13:$AR$18,N10,$AT$13:$AT$18)+SUMIF($AS$13:$AS$18,N10,$AU$13:$AU$18) -> 1 | R10: =-SUMIF($AR$13:$AR$18,N10,$AU$13:$AU$18)-SUMIF($AS$13:$AS$18,N10,$AT$13:$AT$18) -> -9 | S10: =SUM(Q10:R10) -> -8 | T10: =RANK(P10,$P$9:$P$12,0) -> 4 | U10: =RANK(S10,$S$9:$S$12,0) -> 4 | V10: =RANK(Q10,$Q$9:$Q$12,0) -> 4 | W10: =W9+0.001 -> 0.002 | X10: =IF(COUNTIF($T$9:$T$12,T10)>1,U10,0) -> 0 | Y10: =IF(X10=MAX($X$9:$X$12),0.2,0) -> 0 | Z10: =Y10+T10 -> 4 | AA10: =IF(COUNTIF($Z$9:$Z$12,Z10)>1,V10,0) -> 0 | AB10: =IF(AA10=MAX($AA$9:$AA$12),0.1,0) -> 0 | AC10: =Z10+AB10+W10 -> 4.002 | AD10: =_xlfn.RANK.EQ(AC10,$AC$9:$AC$12,1) -> 4 | AF10: 2 | AG10: =INDEX($N$9:$N$12,MATCH($AF10,$AD$9:$AD$12,0),) -> USA | AH10: =INDEX($P$9:$P$12,MATCH($AF10,$AD$9:$AD$12,0),) -> 5 | AI10: =INDEX($S$9:$S$12,MATCH($AF10,$AD$9:$AD$12,0),) -> 2 | AJ10: =INDEX($Q$9:$Q$12,MATCH($AF10,$AD$9:$AD$12,0),) -> 6 | AL10: =COUNTIF(Tippa!$J$34:$J$37,Beräkningar!AF10) -> 1 | AM10: =Tippa!J35 -> 2 | AN10: =AM10&"B" -> 2B | AO10: =INDEX(AM9:AM12,MATCH(N10,AG9:AG12,0),) -> 4 | AP10: =Tippa!A28 -> A6 | AQ10: =Tippa!C28 -> Nederländerna - Qatar | AR10: =INDEX($G$4:$G$51,MATCH(AP10,$K$4:$K$51,0),) -> Nederländerna | AS10: =INDEX($H$4:$H$51,MATCH(AP10,$K$4:$K$51,0),) -> Qatar | AT10: =Tippa!G28 -> 3 | AU10: =Tippa!H28 -> 0 | AV10: =IF(AT10="-",0,IF(AT10>AU10,3,IF(AT10=AU10,1,0))) -> 3 | AW10: =IF(AT10="-",0,IF(AU10>AT10,3,IF(AU10=AT10,1,0))) -> 0 | AY10: 6. Gjorda mål i matcherna mellan likaplacerade lag | AZ10: EJ OK
B11: Tis 22/11 | C11: 0.58333333 | D11: D3-D4 | E11: =LEFT(D11,2) -> D3 | F11: =RIGHT(D11,2) -> D4 | G11: =INDEX($N$4:$N$42,MATCH(E11,$M$4:$M$42,0)) -> Danmark | H11: =INDEX($N$4:$N$42,MATCH(F11,$M$4:$M$42,0)) -> Tunisien | I11: =LEFT(D11,1) -> D | J11: =COUNTIF($I$4:I11,I11) -> 2 | K11: =I11&J11 -> D2 | M11: B3 | N11: USA | P11: =SUMIF($AR$13:$AR$18,N11,$AV$13:$AV$18)+SUMIF($AS$13:$AS$18,N11,$AW$13:$AW$18) -> 5 | Q11: =SUMIF($AR$13:$AR$18,N11,$AT$13:$AT$18)+SUMIF($AS$13:$AS$18,N11,$AU$13:$AU$18) -> 6 | R11: =-SUMIF($AR$13:$AR$18,N11,$AU$13:$AU$18)-SUMIF($AS$13:$AS$18,N11,$AT$13:$AT$18) -> -4 | S11: =SUM(Q11:R11) -> 2 | T11: =RANK(P11,$P$9:$P$12,0) -> 1 | U11: =RANK(S11,$S$9:$S$12,0) -> 2 | V11: =RANK(Q11,$Q$9:$Q$12,0) -> 2 | W11: =W10+0.001 -> 0.003 | X11: =IF(COUNTIF($T$9:$T$12,T11)>1,U11,0) -> 2 | Y11: =IF(X11=MAX($X$9:$X$12),0.2,0) -> 0.2 | Z11: =Y11+T11 -> 1.2 | AA11: =IF(COUNTIF($Z$9:$Z$12,Z11)>1,V11,0) -> 2 | AB11: =IF(AA11=MAX($AA$9:$AA$12),0.1,0) -> 0 | AC11: =Z11+AB11+W11 -> 1.203 | AD11: =_xlfn.RANK.EQ(AC11,$AC$9:$AC$12,1) -> 2 | AF11: 3 | AG11: =INDEX($N$9:$N$12,MATCH($AF11,$AD$9:$AD$12,0),) -> Wales | AH11: =INDEX($P$9:$P$12,MATCH($AF11,$AD$9:$AD$12,0),) -> 5 | AI11: =INDEX($S$9:$S$12,MATCH($AF11,$AD$9:$AD$12,0),) -> 2 | AJ11: =INDEX($Q$9:$Q$12,MATCH($AF11,$AD$9:$AD$12,0),) -> 4 | AL11: =COUNTIF(Tippa!$J$34:$J$37,Beräkningar!AF11) -> 1 | AM11: =Tippa!J36 -> 3 | AN11: =AM11&"B" -> 3B | AO11: =INDEX(AM9:AM12,MATCH(N11,AG9:AG12,0),) -> 2 | AY11: 7. Fair play-poäng | AZ11: EJ OK
B12: Ons 23/11 | C12: 0.58333333 | D12: E3-E4 | E12: =LEFT(D12,2) -> E3 | F12: =RIGHT(D12,2) -> E4 | G12: =INDEX($N$4:$N$42,MATCH(E12,$M$4:$M$42,0)) -> Tyskland | H12: =INDEX($N$4:$N$42,MATCH(F12,$M$4:$M$42,0)) -> Japan | I12: =LEFT(D12,1) -> E | J12: =COUNTIF($I$4:I12,I12) -> 1 | K12: =I12&J12 -> E1 | M12: B4 | N12: Wales | P12: =SUMIF($AR$13:$AR$18,N12,$AV$13:$AV$18)+SUMIF($AS$13:$AS$18,N12,$AW$13:$AW$18) -> 5 | Q12: =SUMIF($AR$13:$AR$18,N12,$AT$13:$AT$18)+SUMIF($AS$13:$AS$18,N12,$AU$13:$AU$18) -> 4 | R12: =-SUMIF($AR$13:$AR$18,N12,$AU$13:$AU$18)-SUMIF($AS$13:$AS$18,N12,$AT$13:$AT$18) -> -2 | S12: =SUM(Q12:R12) -> 2 | T12: =RANK(P12,$P$9:$P$12,0) -> 1 | U12: =RANK(S12,$S$9:$S$12,0) -> 2 | V12: =RANK(Q12,$Q$9:$Q$12,0) -> 3 | W12: =W11+0.001 -> 0.004 | X12: =IF(COUNTIF($T$9:$T$12,T12)>1,U12,0) -> 2 | Y12: =IF(X12=MAX($X$9:$X$12),0.2,0) -> 0.2 | Z12: =Y12+T12 -> 1.2 | AA12: =IF(COUNTIF($Z$9:$Z$12,Z12)>1,V12,0) -> 3 | AB12: =IF(AA12=MAX($AA$9:$AA$12),0.1,0) -> 0.1 | AC12: =Z12+AB12+W12 -> 1.304 | AD12: =_xlfn.RANK.EQ(AC12,$AC$9:$AC$12,1) -> 3 | AF12: 4 | AG12: =INDEX($N$9:$N$12,MATCH($AF12,$AD$9:$AD$12,0),) -> Iran | AH12: =INDEX($P$9:$P$12,MATCH($AF12,$AD$9:$AD$12,0),) -> 0 | AI12: =INDEX($S$9:$S$12,MATCH($AF12,$AD$9:$AD$12,0),) -> -8 | AJ12: =INDEX($Q$9:$Q$12,MATCH($AF12,$AD$9:$AD$12,0),) -> 1 | AL12: =COUNTIF(Tippa!$J$34:$J$37,Beräkningar!AF12) -> 1 | AM12: =Tippa!J37 -> 4 | AN12: =AM12&"B" -> 4B | AO12: =INDEX(AM9:AM12,MATCH(N12,AG9:AG12,0),) -> 3 | AQ12: Grupp B | AT12: Resultat | AV12: Poäng | AY12: 8. Lottdragning | AZ12: EJ OK
B13: Ons 23/11 | C13: 0.83333333 | D13: F1-F2 | E13: =LEFT(D13,2) -> F1 | F13: =RIGHT(D13,2) -> F2 | G13: =INDEX($N$4:$N$42,MATCH(E13,$M$4:$M$42,0)) -> Belgien | H13: =INDEX($N$4:$N$42,MATCH(F13,$M$4:$M$42,0)) -> Kanada | I13: =LEFT(D13,1) -> F | J13: =COUNTIF($I$4:I13,I13) -> 1 | K13: =I13&J13 -> F1 | AP13: =Tippa!A34 -> B1 | AQ13: =Tippa!C34 -> USA - Wales | AR13: =INDEX($G$4:$G$51,MATCH(AP13,$K$4:$K$51,0),) -> USA | AS13: =INDEX($H$4:$H$51,MATCH(AP13,$K$4:$K$51,0),) -> Wales | AT13: =Tippa!G34 -> 1 | AU13: =Tippa!H34 -> 1 | AV13: =IF(AT13="-",0,IF(AT13>AU13,3,IF(AT13=AU13,1,0))) -> 1 | AW13: =IF(AT13="-",0,IF(AU13>AT13,3,IF(AU13=AT13,1,0))) -> 1
B14: Ons 23/11 | C14: 0.70833333 | D14: E1-E2 | E14: =LEFT(D14,2) -> E1 | F14: =RIGHT(D14,2) -> E2 | G14: =INDEX($N$4:$N$42,MATCH(E14,$M$4:$M$42,0)) -> Spanien | H14: =INDEX($N$4:$N$42,MATCH(F14,$M$4:$M$42,0)) -> Costa Rica | I14: =LEFT(D14,1) -> E | J14: =COUNTIF($I$4:I14,I14) -> 2 | K14: =I14&J14 -> E2 | M14: C1 | N14: Argentina | P14: =SUMIF($AR$21:$AR$26,N14,$AV$21:$AV$26)+SUMIF($AS$21:$AS$26,N14,$AW$21:$AW$26) -> 7 | Q14: =SUMIF($AR$21:$AR$26,N14,$AT$21:$AT$26)+SUMIF($AS$21:$AS$26,N14,$AU$21:$AU$26) -> 8 | R14: =-SUMIF($AR$21:$AR$26,N14,$AU$21:$AU$26)-SUMIF($AS$21:$AS$26,N14,$AT$21:$AT$26) -> -3 | S14: =SUM(Q14:R14) -> 5 | T14: =RANK(P14,$P$14:$P$17,0) -> 1 | U14: =RANK(S14,$S$14:$S$17,0) -> 1 | V14: =RANK(Q14,$Q$14:$Q$17,0) -> 1 | W14: 0.001 | X14: =IF(COUNTIF($T$14:$T$17,T14)>1,U14,0) -> 1 | Y14: =IF(X14=MAX($X$14:$X$17),0.2,0) -> 0 | Z14: =Y14+T14 -> 1 | AA14: =IF(COUNTIF($Z$14:$Z$17,Z14)>1,V14,0) -> 0 | AB14: =IF(AA14=MAX($AA$14:$AA$17),0.1,0) -> 0.1 | AC14: =Z14+AB14+W14 -> 1.101 | AD14: =_xlfn.RANK.EQ(AC14,$AC$14:$AC$17,1) -> 1 | AF14: 1 | AG14: =INDEX($N$14:$N$17,MATCH($AF14,$AD$14:$AD$17,0),) -> Argentina | AH14: =INDEX($P$14:$P$17,MATCH($AF14,$AD$14:$AD$17,0),) -> 7 | AI14: =INDEX($S$14:$S$17,MATCH($AF14,$AD$14:$AD$17,0),) -> 5 | AJ14: =INDEX($Q$14:$Q$17,MATCH($AF14,$AD$14:$AD$17,0),) -> 8 | AL14: =COUNTIF(Tippa!$J$45:$J$48,Beräkningar!AF14) -> 1 | AM14: =Tippa!J45 -> 1 | AN14: =AM14&"C" -> 1C | AO14: =INDEX(AM14:AM17,MATCH(N14,AG14:AG17,0),) -> 1 | AP14: =Tippa!A35 -> B2 | AQ14: =Tippa!C35 -> England - Iran | AR14: =INDEX($G$4:$G$51,MATCH(AP14,$K$4:$K$51,0),) -> England | AS14: =INDEX($H$4:$H$51,MATCH(AP14,$K$4:$K$51,0),) -> Iran | AT14: =Tippa!G35 -> 4 | AU14: =Tippa!H35 -> 0 | AV14: =IF(AT14="-",0,IF(AT14>AU14,3,IF(AT14=AU14,1,0))) -> 3 | AW14: =IF(AT14="-",0,IF(AU14>AT14,3,IF(AU14=AT14,1,0))) -> 0
B15: Ons 23/11 | C15: 0.45833333 | D15: F3-F4 | E15: =LEFT(D15,2) -> F3 | F15: =RIGHT(D15,2) -> F4 | G15: =INDEX($N$4:$N$42,MATCH(E15,$M$4:$M$42,0)) -> Marocko | H15: =INDEX($N$4:$N$42,MATCH(F15,$M$4:$M$42,0)) -> Kroatien | I15: =LEFT(D15,1) -> F | J15: =COUNTIF($I$4:I15,I15) -> 2 | K15: =I15&J15 -> F2 | M15: C2 | N15: Saudiarabien | P15: =SUMIF($AR$21:$AR$26,N15,$AV$21:$AV$26)+SUMIF($AS$21:$AS$26,N15,$AW$21:$AW$26) -> 0 | Q15: =SUMIF($AR$21:$AR$26,N15,$AT$21:$AT$26)+SUMIF($AS$21:$AS$26,N15,$AU$21:$AU$26) -> 0 | R15: =-SUMIF($AR$21:$AR$26,N15,$AU$21:$AU$26)-SUMIF($AS$21:$AS$26,N15,$AT$21:$AT$26) -> -7 | S15: =SUM(Q15:R15) -> -7 | T15: =RANK(P15,$P$14:$P$17,0) -> 4 | U15: =RANK(S15,$S$14:$S$17,0) -> 4 | V15: =RANK(Q15,$Q$14:$Q$17,0) -> 4 | W15: =W14+0.001 -> 0.002 | X15: =IF(COUNTIF($T$14:$T$17,T15)>1,U15,0) -> 0 | Y15: =IF(X15=MAX($X$14:$X$17),0.2,0) -> 0 | Z15: =Y15+T15 -> 4 | AA15: =IF(COUNTIF($Z$14:$Z$17,Z15)>1,V15,0) -> 0 | AB15: =IF(AA15=MAX($AA$14:$AA$17),0.1,0) -> 0.1 | AC15: =Z15+AB15+W15 -> 4.102 | AD15: =_xlfn.RANK.EQ(AC15,$AC$14:$AC$17,1) -> 4 | AF15: 2 | AG15: =INDEX($N$14:$N$17,MATCH($AF15,$AD$14:$AD$17,0),) -> Mexiko | AH15: =INDEX($P$14:$P$17,MATCH($AF15,$AD$14:$AD$17,0),) -> 7 | AI15: =INDEX($S$14:$S$17,MATCH($AF15,$AD$14:$AD$17,0),) -> 3 | AJ15: =INDEX($Q$14:$Q$17,MATCH($AF15,$AD$14:$AD$17,0),) -> 6 | AL15: =COUNTIF(Tippa!$J$45:$J$48,Beräkningar!AF15) -> 1 | AM15: =Tippa!J46 -> 2 | AN15: =AM15&"C" -> 2C | AO15: =INDEX(AM14:AM17,MATCH(N15,AG14:AG17,0),) -> 4 | AP15: =Tippa!A36 -> B3 | AQ15: =Tippa!C36 -> England - USA | AR15: =INDEX($G$4:$G$51,MATCH(AP15,$K$4:$K$51,0),) -> England | AS15: =INDEX($H$4:$H$51,MATCH(AP15,$K$4:$K$51,0),) -> USA | AT15: =Tippa!G36 -> 2 | AU15: =Tippa!H36 -> 2 | AV15: =IF(AT15="-",0,IF(AT15>AU15,3,IF(AT15=AU15,1,0))) -> 1 | AW15: =IF(AT15="-",0,IF(AU15>AT15,3,IF(AU15=AT15,1,0))) -> 1
B16: Tor 24/11 | C16: 0.83333333 | D16: G1-G2 | E16: =LEFT(D16,2) -> G1 | F16: =RIGHT(D16,2) -> G2 | G16: =INDEX($N$4:$N$42,MATCH(E16,$M$4:$M$42,0)) -> Brasilien | H16: =INDEX($N$4:$N$42,MATCH(F16,$M$4:$M$42,0)) -> Serbien | I16: =LEFT(D16,1) -> G | J16: =COUNTIF($I$4:I16,I16) -> 1 | K16: =I16&J16 -> G1 | M16: C3 | N16: Mexiko | P16: =SUMIF($AR$21:$AR$26,N16,$AV$21:$AV$26)+SUMIF($AS$21:$AS$26,N16,$AW$21:$AW$26) -> 7 | Q16: =SUMIF($AR$21:$AR$26,N16,$AT$21:$AT$26)+SUMIF($AS$21:$AS$26,N16,$AU$21:$AU$26) -> 6 | R16: =-SUMIF($AR$21:$AR$26,N16,$AU$21:$AU$26)-SUMIF($AS$21:$AS$26,N16,$AT$21:$AT$26) -> -3 | S16: =SUM(Q16:R16) -> 3 | T16: =RANK(P16,$P$14:$P$17,0) -> 1 | U16: =RANK(S16,$S$14:$S$17,0) -> 2 | V16: =RANK(Q16,$Q$14:$Q$17,0) -> 2 | W16: =W15+0.001 -> 0.003 | X16: =IF(COUNTIF($T$14:$T$17,T16)>1,U16,0) -> 2 | Y16: =IF(X16=MAX($X$14:$X$17),0.2,0) -> 0.2 | Z16: =Y16+T16 -> 1.2 | AA16: =IF(COUNTIF($Z$14:$Z$17,Z16)>1,V16,0) -> 0 | AB16: =IF(AA16=MAX($AA$14:$AA$17),0.1,0) -> 0.1 | AC16: =Z16+AB16+W16 -> 1.303 | AD16: =_xlfn.RANK.EQ(AC16,$AC$14:$AC$17,1) -> 2 | AF16: 3 | AG16: =INDEX($N$14:$N$17,MATCH($AF16,$AD$14:$AD$17,0),) -> Polen | AH16: =INDEX($P$14:$P$17,MATCH($AF16,$AD$14:$AD$17,0),) -> 3 | AI16: =INDEX($S$14:$S$17,MATCH($AF16,$AD$14:$AD$17,0),) -> -1 | AJ16: =INDEX($Q$14:$Q$17,MATCH($AF16,$AD$14:$AD$17,0),) -> 3 | AL16: =COUNTIF(Tippa!$J$45:$J$48,Beräkningar!AF16) -> 1 | AM16: =Tippa!J47 -> 3 | AN16: =AM16&"C" -> 3C | AO16: =INDEX(AM14:AM17,MATCH(N16,AG14:AG17,0),) -> 2 | AP16: =Tippa!A37 -> B4 | AQ16: =Tippa!C37 -> Wales - Iran | AR16: =INDEX($G$4:$G$51,MATCH(AP16,$K$4:$K$51,0),) -> Wales | AS16: =INDEX($H$4:$H$51,MATCH(AP16,$K$4:$K$51,0),) -> Iran | AT16: =Tippa!G37 -> 2 | AU16: =Tippa!H37 -> 0 | AV16: =IF(AT16="-",0,IF(AT16>AU16,3,IF(AT16=AU16,1,0))) -> 3 | AW16: =IF(AT16="-",0,IF(AU16>AT16,3,IF(AU16=AT16,1,0))) -> 0
B17: Tor 24/11 | C17: 0.45833333 | D17: G3-G4 | E17: =LEFT(D17,2) -> G3 | F17: =RIGHT(D17,2) -> G4 | G17: =INDEX($N$4:$N$42,MATCH(E17,$M$4:$M$42,0)) -> Schweiz | H17: =INDEX($N$4:$N$42,MATCH(F17,$M$4:$M$42,0)) -> Kamerun | I17: =LEFT(D17,1) -> G | J17: =COUNTIF($I$4:I17,I17) -> 2 | K17: =I17&J17 -> G2 | M17: C4 | N17: Polen | P17: =SUMIF($AR$21:$AR$26,N17,$AV$21:$AV$26)+SUMIF($AS$21:$AS$26,N17,$AW$21:$AW$26) -> 3 | Q17: =SUMIF($AR$21:$AR$26,N17,$AT$21:$AT$26)+SUMIF($AS$21:$AS$26,N17,$AU$21:$AU$26) -> 3 | R17: =-SUMIF($AR$21:$AR$26,N17,$AU$21:$AU$26)-SUMIF($AS$21:$AS$26,N17,$AT$21:$AT$26) -> -4 | S17: =SUM(Q17:R17) -> -1 | T17: =RANK(P17,$P$14:$P$17,0) -> 3 | U17: =RANK(S17,$S$14:$S$17,0) -> 3 | V17: =RANK(Q17,$Q$14:$Q$17,0) -> 3 | W17: =W16+0.001 -> 0.004 | X17: =IF(COUNTIF($T$14:$T$17,T17)>1,U17,0) -> 0 | Y17: =IF(X17=MAX($X$14:$X$17),0.2,0) -> 0 | Z17: =Y17+T17 -> 3 | AA17: =IF(COUNTIF($Z$14:$Z$17,Z17)>1,V17,0) -> 0 | AB17: =IF(AA17=MAX($AA$14:$AA$17),0.1,0) -> 0.1 | AC17: =Z17+AB17+W17 -> 3.104 | AD17: =_xlfn.RANK.EQ(AC17,$AC$14:$AC$17,1) -> 3 | AF17: 4 | AG17: =INDEX($N$14:$N$17,MATCH($AF17,$AD$14:$AD$17,0),) -> Saudiarabien | AH17: =INDEX($P$14:$P$17,MATCH($AF17,$AD$14:$AD$17,0),) -> 0 | AI17: =INDEX($S$14:$S$17,MATCH($AF17,$AD$14:$AD$17,0),) -> -7 | AJ17: =INDEX($Q$14:$Q$17,MATCH($AF17,$AD$14:$AD$17,0),) -> 0 | AL17: =COUNTIF(Tippa!$J$45:$J$48,Beräkningar!AF17) -> 1 | AM17: =Tippa!J48 -> 4 | AN17: =AM17&"C" -> 4C | AO17: =INDEX(AM14:AM17,MATCH(N17,AG14:AG17,0),) -> 3 | AP17: =Tippa!A38 -> B5 | AQ17: =Tippa!C38 -> Iran - USA | AR17: =INDEX($G$4:$G$51,MATCH(AP17,$K$4:$K$51,0),) -> Iran | AS17: =INDEX($H$4:$H$51,MATCH(AP17,$K$4:$K$51,0),) -> USA | AT17: =Tippa!G38 -> 1 | AU17: =Tippa!H38 -> 3 | AV17: =IF(AT17="-",0,IF(AT17>AU17,3,IF(AT17=AU17,1,0))) -> 0 | AW17: =IF(AT17="-",0,IF(AU17>AT17,3,IF(AU17=AT17,1,0))) -> 3
B18: Tor 24/11 | C18: 0.70833333 | D18: H1-H2 | E18: =LEFT(D18,2) -> H1 | F18: =RIGHT(D18,2) -> H2 | G18: =INDEX($N$4:$N$42,MATCH(E18,$M$4:$M$42,0)) -> Portugal | H18: =INDEX($N$4:$N$42,MATCH(F18,$M$4:$M$42,0)) -> Ghana | I18: =LEFT(D18,1) -> H | J18: =COUNTIF($I$4:I18,I18) -> 1 | K18: =I18&J18 -> H1 | AP18: =Tippa!A39 -> B6 | AQ18: =Tippa!C39 -> Wales - England | AR18: =INDEX($G$4:$G$51,MATCH(AP18,$K$4:$K$51,0),) -> Wales | AS18: =INDEX($H$4:$H$51,MATCH(AP18,$K$4:$K$51,0),) -> England | AT18: =Tippa!G39 -> 1 | AU18: =Tippa!H39 -> 1 | AV18: =IF(AT18="-",0,IF(AT18>AU18,3,IF(AT18=AU18,1,0))) -> 1 | AW18: =IF(AT18="-",0,IF(AU18>AT18,3,IF(AU18=AT18,1,0))) -> 1
B19: Tor 24/11 | C19: 0.58333333 | D19: H3-H4 | E19: =LEFT(D19,2) -> H3 | F19: =RIGHT(D19,2) -> H4 | G19: =INDEX($N$4:$N$42,MATCH(E19,$M$4:$M$42,0)) -> Uruguay | H19: =INDEX($N$4:$N$42,MATCH(F19,$M$4:$M$42,0)) -> Sydkorea | I19: =LEFT(D19,1) -> H | J19: =COUNTIF($I$4:I19,I19) -> 2 | K19: =I19&J19 -> H2 | M19: D1 | N19: Frankrike | P19: =SUMIF($AR$29:$AR$34,N19,$AV$29:$AV$34)+SUMIF($AS$29:$AS$34,N19,$AW$29:$AW$34) -> 9 | Q19: =SUMIF($AR$29:$AR$34,N19,$AT$29:$AT$34)+SUMIF($AS$29:$AS$34,N19,$AU$29:$AU$34) -> 7 | R19: =-SUMIF($AR$29:$AR$34,N19,$AU$29:$AU$34)-SUMIF($AS$29:$AS$34,N19,$AT$29:$AT$34) -> 0 | S19: =SUM(Q19:R19) -> 7 | T19: =RANK(P19,$P$19:$P$22,0) -> 1 | U19: =RANK(S19,$S$19:$S$22,0) -> 1 | V19: =RANK(Q19,$Q$19:$Q$22,0) -> 1 | W19: 0.001 | X19: =IF(COUNTIF($T$19:$T$22,T19)>1,U19,0) -> 0 | Y19: =IF(X19=MAX($X$19:$X$22),0.2,0) -> 0 | Z19: =Y19+T19 -> 1 | AA19: =IF(COUNTIF($Z$19:$Z$22,Z19)>1,V19,0) -> 0 | AB19: =IF(AA19=MAX($AA$19:$AA$22),0.1,0) -> 0.1 | AC19: =Z19+AB19+W19 -> 1.101 | AD19: =_xlfn.RANK.EQ(AC19,$AC$19:$AC$22,1) -> 1 | AF19: 1 | AG19: =INDEX($N$19:$N$22,MATCH($AF19,$AD$19:$AD$22,0),) -> Frankrike | AH19: =INDEX($P$19:$P$22,MATCH($AF19,$AD$19:$AD$22,0),) -> 9 | AI19: =INDEX($S$19:$S$22,MATCH($AF19,$AD$19:$AD$22,0),) -> 7 | AJ19: =INDEX($Q$19:$Q$22,MATCH($AF19,$AD$19:$AD$22,0),) -> 7 | AL19: =COUNTIF(Tippa!$J$56:$J$59,Beräkningar!AF19) -> 1 | AM19: =Tippa!J56 -> 1 | AN19: =AM19&"D" -> 1D | AO19: =INDEX(AM19:AM22,MATCH(N19,AG19:AG22,0),) -> 1
B20: Fre 25/11 | C20: 0.58333333 | D20: A1-A3 | E20: =LEFT(D20,2) -> A1 | F20: =RIGHT(D20,2) -> A3 | G20: =INDEX($N$4:$N$42,MATCH(E20,$M$4:$M$42,0)) -> Qatar | H20: =INDEX($N$4:$N$42,MATCH(F20,$M$4:$M$42,0)) -> Senegal | I20: =LEFT(D20,1) -> A | J20: =COUNTIF($I$4:I20,I20) -> 3 | K20: =I20&J20 -> A3 | M20: D2 | N20: Australien | P20: =SUMIF($AR$29:$AR$34,N20,$AV$29:$AV$34)+SUMIF($AS$29:$AS$34,N20,$AW$29:$AW$34) -> 1 | Q20: =SUMIF($AR$29:$AR$34,N20,$AT$29:$AT$34)+SUMIF($AS$29:$AS$34,N20,$AU$29:$AU$34) -> 1 | R20: =-SUMIF($AR$29:$AR$34,N20,$AU$29:$AU$34)-SUMIF($AS$29:$AS$34,N20,$AT$29:$AT$34) -> -8 | S20: =SUM(Q20:R20) -> -7 | T20: =RANK(P20,$P$19:$P$22,0) -> 3 | U20: =RANK(S20,$S$19:$S$22,0) -> 4 | V20: =RANK(Q20,$Q$19:$Q$22,0) -> 4 | W20: =W19+0.001 -> 0.002 | X20: =IF(COUNTIF($T$19:$T$22,T20)>1,U20,0) -> 4 | Y20: =IF(X20=MAX($X$19:$X$22),0.2,0) -> 0.2 | Z20: =Y20+T20 -> 3.2 | AA20: =IF(COUNTIF($Z$19:$Z$22,Z20)>1,V20,0) -> 0 | AB20: =IF(AA20=MAX($AA$19:$AA$22),0.1,0) -> 0.1 | AC20: =Z20+AB20+W20 -> 3.302 | AD20: =_xlfn.RANK.EQ(AC20,$AC$19:$AC$22,1) -> 4 | AF20: 2 | AG20: =INDEX($N$19:$N$22,MATCH($AF20,$AD$19:$AD$22,0),) -> Danmark | AH20: =INDEX($P$19:$P$22,MATCH($AF20,$AD$19:$AD$22,0),) -> 6 | AI20: =INDEX($S$19:$S$22,MATCH($AF20,$AD$19:$AD$22,0),) -> 3 | AJ20: =INDEX($Q$19:$Q$22,MATCH($AF20,$AD$19:$AD$22,0),) -> 5 | AL20: =COUNTIF(Tippa!$J$56:$J$59,Beräkningar!AF20) -> 1 | AM20: =Tippa!J57 -> 2 | AN20: =AM20&"D" -> 2D | AO20: =INDEX(AM19:AM22,MATCH(N20,AG19:AG22,0),) -> 4 | AQ20: Grupp C | AT20: Resultat | AV20: Poäng
B21: Fre 25/11 | C21: 0.83333333 | D21: B1-B3 | E21: =LEFT(D21,2) -> B1 | F21: =RIGHT(D21,2) -> B3 | G21: =INDEX($N$4:$N$42,MATCH(E21,$M$4:$M$42,0)) -> England | H21: =INDEX($N$4:$N$42,MATCH(F21,$M$4:$M$42,0)) -> USA | I21: =LEFT(D21,1) -> B | J21: =COUNTIF($I$4:I21,I21) -> 3 | K21: =I21&J21 -> B3 | M21: D3 | N21: Danmark | P21: =SUMIF($AR$29:$AR$34,N21,$AV$29:$AV$34)+SUMIF($AS$29:$AS$34,N21,$AW$29:$AW$34) -> 6 | Q21: =SUMIF($AR$29:$AR$34,N21,$AT$29:$AT$34)+SUMIF($AS$29:$AS$34,N21,$AU$29:$AU$34) -> 5 | R21: =-SUMIF($AR$29:$AR$34,N21,$AU$29:$AU$34)-SUMIF($AS$29:$AS$34,N21,$AT$29:$AT$34) -> -2 | S21: =SUM(Q21:R21) -> 3 | T21: =RANK(P21,$P$19:$P$22,0) -> 2 | U21: =RANK(S21,$S$19:$S$22,0) -> 2 | V21: =RANK(Q21,$Q$19:$Q$22,0) -> 2 | W21: =W20+0.001 -> 0.003 | X21: =IF(COUNTIF($T$19:$T$22,T21)>1,U21,0) -> 0 | Y21: =IF(X21=MAX($X$19:$X$22),0.2,0) -> 0 | Z21: =Y21+T21 -> 2 | AA21: =IF(COUNTIF($Z$19:$Z$22,Z21)>1,V21,0) -> 0 | AB21: =IF(AA21=MAX($AA$19:$AA$22),0.1,0) -> 0.1 | AC21: =Z21+AB21+W21 -> 2.103 | AD21: =_xlfn.RANK.EQ(AC21,$AC$19:$AC$22,1) -> 2 | AF21: 3 | AG21: =INDEX($N$19:$N$22,MATCH($AF21,$AD$19:$AD$22,0),) -> Tunisien | AH21: =INDEX($P$19:$P$22,MATCH($AF21,$AD$19:$AD$22,0),) -> 1 | AI21: =INDEX($S$19:$S$22,MATCH($AF21,$AD$19:$AD$22,0),) -> -3 | AJ21: =INDEX($Q$19:$Q$22,MATCH($AF21,$AD$19:$AD$22,0),) -> 2 | AL21: =COUNTIF(Tippa!$J$56:$J$59,Beräkningar!AF21) -> 1 | AM21: =Tippa!J58 -> 3 | AN21: =AM21&"D" -> 3D | AO21: =INDEX(AM19:AM22,MATCH(N21,AG19:AG22,0),) -> 2 | AP21: =Tippa!A45 -> C1 | AQ21: =Tippa!C45 -> Argentina - Saudiarabien | AR21: =INDEX($G$4:$G$51,MATCH(AP21,$K$4:$K$51,0),) -> Argentina | AS21: =INDEX($H$4:$H$51,MATCH(AP21,$K$4:$K$51,0),) -> Saudiarabien | AT21: =Tippa!G45 -> 4 | AU21: =Tippa!H45 -> 0 | AV21: =IF(AT21="-",0,IF(AT21>AU21,3,IF(AT21=AU21,1,0))) -> 3 | AW21: =IF(AT21="-",0,IF(AU21>AT21,3,IF(AU21=AT21,1,0))) -> 0
B22: Fre 25/11 | C22: 0.70833333 | D22: A4-A2 | E22: =LEFT(D22,2) -> A4 | F22: =RIGHT(D22,2) -> A2 | G22: =INDEX($N$4:$N$42,MATCH(E22,$M$4:$M$42,0)) -> Nederländerna | H22: =INDEX($N$4:$N$42,MATCH(F22,$M$4:$M$42,0)) -> Ecuador | I22: =LEFT(D22,1) -> A | J22: =COUNTIF($I$4:I22,I22) -> 4 | K22: =I22&J22 -> A4 | M22: D4 | N22: Tunisien | P22: =SUMIF($AR$29:$AR$34,N22,$AV$29:$AV$34)+SUMIF($AS$29:$AS$34,N22,$AW$29:$AW$34) -> 1 | Q22: =SUMIF($AR$29:$AR$34,N22,$AT$29:$AT$34)+SUMIF($AS$29:$AS$34,N22,$AU$29:$AU$34) -> 2 | R22: =-SUMIF($AR$29:$AR$34,N22,$AU$29:$AU$34)-SUMIF($AS$29:$AS$34,N22,$AT$29:$AT$34) -> -5 | S22: =SUM(Q22:R22) -> -3 | T22: =RANK(P22,$P$19:$P$22,0) -> 3 | U22: =RANK(S22,$S$19:$S$22,0) -> 3 | V22: =RANK(Q22,$Q$19:$Q$22,0) -> 3 | W22: =W21+0.001 -> 0.004 | X22: =IF(COUNTIF($T$19:$T$22,T22)>1,U22,0) -> 3 | Y22: =IF(X22=MAX($X$19:$X$22),0.2,0) -> 0 | Z22: =Y22+T22 -> 3 | AA22: =IF(COUNTIF($Z$19:$Z$22,Z22)>1,V22,0) -> 0 | AB22: =IF(AA22=MAX($AA$19:$AA$22),0.1,0) -> 0.1 | AC22: =Z22+AB22+W22 -> 3.104 | AD22: =_xlfn.RANK.EQ(AC22,$AC$19:$AC$22,1) -> 3 | AF22: 4 | AG22: =INDEX($N$19:$N$22,MATCH($AF22,$AD$19:$AD$22,0),) -> Australien | AH22: =INDEX($P$19:$P$22,MATCH($AF22,$AD$19:$AD$22,0),) -> 1 | AI22: =INDEX($S$19:$S$22,MATCH($AF22,$AD$19:$AD$22,0),) -> -7 | AJ22: =INDEX($Q$19:$Q$22,MATCH($AF22,$AD$19:$AD$22,0),) -> 1 | AL22: =COUNTIF(Tippa!$J$56:$J$59,Beräkningar!AF22) -> 1 | AM22: =Tippa!J59 -> 4 | AN22: =AM22&"D" -> 4D | AO22: =INDEX(AM19:AM22,MATCH(N22,AG19:AG22,0),) -> 3 | AP22: =Tippa!A46 -> C2 | AQ22: =Tippa!C46 -> Mexiko - Polen | AR22: =INDEX($G$4:$G$51,MATCH(AP22,$K$4:$K$51,0),) -> Mexiko | AS22: =INDEX($H$4:$H$51,MATCH(AP22,$K$4:$K$51,0),) -> Polen | AT22: =Tippa!G46 -> 2 | AU22: =Tippa!H46 -> 1 | AV22: =IF(AT22="-",0,IF(AT22>AU22,3,IF(AT22=AU22,1,0))) -> 3 | AW22: =IF(AT22="-",0,IF(AU22>AT22,3,IF(AU22=AT22,1,0))) -> 0
B23: Fre 25/11 | C23: 0.45833333 | D23: B4-B2 | E23: =LEFT(D23,2) -> B4 | F23: =RIGHT(D23,2) -> B2 | G23: =INDEX($N$4:$N$42,MATCH(E23,$M$4:$M$42,0)) -> Wales | H23: =INDEX($N$4:$N$42,MATCH(F23,$M$4:$M$42,0)) -> Iran | I23: =LEFT(D23,1) -> B | J23: =COUNTIF($I$4:I23,I23) -> 4 | K23: =I23&J23 -> B4 | AP23: =Tippa!A47 -> C3 | AQ23: =Tippa!C47 -> Polen - Saudiarabien | AR23: =INDEX($G$4:$G$51,MATCH(AP23,$K$4:$K$51,0),) -> Polen | AS23: =INDEX($H$4:$H$51,MATCH(AP23,$K$4:$K$51,0),) -> Saudiarabien | AT23: =Tippa!G47 -> 1 | AU23: =Tippa!H47 -> 0 | AV23: =IF(AT23="-",0,IF(AT23>AU23,3,IF(AT23=AU23,1,0))) -> 3 | AW23: =IF(AT23="-",0,IF(AU23>AT23,3,IF(AU23=AT23,1,0))) -> 0
